Workbook

Sheet QA Table
F5: Sediment | L5: 18GE01C01 | P5: 18GE01C01 | T5: 18GE01C01 | Y5: 18GE01C01 | AD5: 18GE01C01 | AI5: 18GE01C01
B6: FRB | C6: LDn | D6: FDn | E6: DO | F6: LDn | G6: FDn | I6: FRB | J6: ER 63 | K6: SRF | L6: 24GE00S21 | M6: LDn | N6: ER 10 | O6: MID | P6: 24GE00S63 | Q6: FDn | R6: ER 15M | S6: 10M | T6: 24GE00S03 | V6: DO | W6: ER 09 | X6: SRF | Y6: 24GE00S41 | AA6: Sediment | AB6: ER 91M | AC6: Benthos | AD6: 24GE03S76 | AF6: Sediment | AG6: ER 61 | AH6: Benthos | AI6: 24GE03S56
B7: SRF | C7: MID | D7: 10M | E7: SRF | F7: Benthos | G7: Benthos | J7: ER 38 | K7: SRF | L7: 24GE01S81 | N7: ER 78M | O7: B- | P7: 24GE02S11 | R7: ER 38 | S7: B- | T7: 24GE01S91 | W7: ER 37 | X7: MID | Y7: 24GE01S63 | AA7: LDn | AB7: ER 91M | AC7: Benthos | AD7: 24GE03S78 | AF7: FDn | AG7: ER 61 | AH7: Benthos | AI7: 24GE03S58
B8: ER 63 | C8: ER 10 | D8: ER 15M | E8: ER 09 | F8: ER 91M | G8: ER 61 | J8: ER 60 | K8: SRF | L8: 24GE03S21 | N8: ER 91M | O8: MID | P8: 24GE03S63 | R8: ER 59 | S8: SRF | T8: 24GE03S01 | W8: ER 59 | X8: B- | Y8: 24GE03S11 | AD8: 24GE03S79 | AI8: 24GE03S59
B9: 24GE00S21 | C9: 24GE00S63 | D9: 24GE00S03 | E9: 24GE00S41 | F9: 24GE03S76 | G9: 24GE03S56 | J9: ER 42 | K9: SRF | L9: 22GE04S01 | N9: ER 30 | O9: SRF | P9: 22GE05S41 | R9: ER 78M | S9: 5M | T9: 22GE05S22 | W9: HU 12 | X9: MID | Y9: 24GH00S43
B10: SRF | C10: B- | D10: B- | E10: MID | J10: HU 09 | K10: SRF | L10: 24GH00S21 | N10: HU 06 | O10: MID | P10: 24GH00S03 | R10: HU 93 | S10: B10 | T10: 24GH00S90 | W10: HU 37 | X10: B10 | Y10: 24GH01S50
B11: ER 38 | C11: ER 78M | D11: ER 38 | E11: ER 37 | J11: HU 37 | K11: SRF | L11: 24GH01S41 | N11: HU 38 | O11: MID | P11: 24GH01S63 | R11: HU 38 | S11: SRF | T11: 24GH01S61 | W11: HU 45M | X11: 30M | Y11: 24GH01S85
B12: 24GE01S81 | C12: 24GE02S11 | D12: 24GE01S91 | E12: 24GE01S63 | J12: HU 54M | K12: SRF | L12: 24GH02S41 | N12: HU 53 | O12: SRF | P12: 24GH02S21 | R12: HU 53 | S12: B10 | T12: 24GH02S30 | W12: MI 18M | X12: 50M | Y12: 24GM00S47
B13: SRF | C13: MID | D13: SRF | E13: B- | J13: MI 17 | K13: SRF | L13: 24GM00S21 | N13: MI 19 | O13: MID | P13: 24GM00S63 | R13: MI 11 | S13: SRF | T13: 24GM00S01 | W13: MI 27M | X13: SRF | Y13: 24GM01S01
B14: ER 60 | C14: ER 91M | D14: ER 59 | E14: ER 59 | J14: MI 34 | K14: SRF | L14: 24GM01S41 | N14: MI 32 | O14: MID | P14: 24GM01S23 | R14: MI 34 | S14: MID | T14: 24GM01S43 | W14: MI 40 | X14: B- | Y14: 24GM01S71
B15: 24GE03S21 | C15: 24GE03S63 | D15: 24GE03S01 | E15: 24GE03S11 | J15: MI 40 | K15: SRF | L15: 24GM01S61 | N15: MI 41M | O15: 100M | P15: 24GM01S88 | R15: MI 47 | S15: B10 | T15: 24GM02S10 | W15: ON 63 | X15: B- | Y15: 24GO00S71
B16: SRF | C16: SRF | D16: 5M | E16: MID | J16: ON 60 | K16: SRF | L16: 24GO00S41 | N16: ON 49 | O16: B10 | P16: 24GO00S10 | R16: ON 55M | S16: SRF | T16: 24GO00S21 | W16: ON 41 | X16: MID | Y16: 24GO01S43
B17: ER 42 | C17: ER 30 | D17: ER 78M | E17: ER 36 | J17: ON 25 | K17: SRF | L17: 24GO01S01 | N17: ON 33M | O17: B- | P17: 24GO01S31 | R17: ON 12 | S17: B10 | T17: 24GO00S90 | W17: SU 01M | X17: 10M | Y17: 24GS00S03
B18: 22GE04S01 | C18: 22GE05S41 | D18: 22GE05S22 | E18: 22GE04S63 | J18: SU 03 | K18: SRF | L18: 24GS00S41 | N18: SU 01M | O18: 40M | P18: 24GS00S06 | R18: SU 04 | S18: B10 | T18: 24GS00S70 | W18: SU 11 | X18: B- | Y18: 24GS02S11
B19: SRF | C19: MID | D19: B10 | E19: MID | J19: SU 07 | K19: SRF | L19: 24GS01S21 | N19: SU 09 | O19: B- | P19: 24GS01S71 | R19: SU 12 | S19: B10 | T19: 24GS02S30 | W19: SU 19 | X19: SRF | Y19: 24GS03S61
B20: HU 09 | C20: HU 06 | D20: HU 93 | E20: HU 12 | J20: SU 15 | K20: SRF | L20: 24GS02S81 | N20: SU 16 | O20: B- | P20: 24GS03S11 | R20: SU 17M | S20: 40M | T20: 24GS03S26
B21: 24GH00S21 | C21: 24GH00S03 | D21: 24GH00S90 | E21: 24GH00S43
B22: SRF | C22: MID | D22: SRF | E22: B10
B23: HU 37 | C23: HU 38 | D23: HU 38 | E23: HU 37
B24: 24GH01S41 | C24: 24GH01S63 | D24: 24GH01S61 | E24: 24GH01S50
B25: SRF | C25: SRF | D25: B10 | E25: 30M
B26: HU 54M | C26: HU 53 | D26: HU 53 | E26: HU 45M
B27: 24GH02S41 | C27: 24GH02S21 | D27: 24GH02S30 | E27: 24GH01S85
B28: SRF | C28: MID | D28: SRF | E28: 50M
B29: MI 17 | C29: MI 19 | D29: MI 11 | E29: MI 18M
B30: 24GM00S21 | C30: 24GM00S63 | D30: 24GM00S01 | E30: 24GM00S47
B31: SRF | C31: MID | D31: MID | E31: SRF
B32: MI 34 | C32: MI 32 | D32: MI 34 | E32: MI 27M
... B35: MI 40 | C35: MI 41M | D35: MI 47 | E35: MI 40
B36: 24GM01S61 | C36: 24GM01S88 | D36: 24GM02S10 | E36: 24GM01S71 | W36: ER 36 | X36: 24GE01S43 | Y36: MID | Z36: RFS
B37: SRF | C37: B10 | D37: SRF | E37: B-
B38: ON 60 | C38: ON 49 | D38: ON 55M | E38: ON 63
B39: 24GO00S41 | C39: 24GO00S10 | D39: 24GO00S21 | E39: 24GO00S71 | R39: ER 09 | S39: SRF | T39: 24GE00S41 | W39: ER 09 | X39: 24GE00S41 | Y39: SRF
B40: SRF | C40: B- | D40: B10 | E40: MID | R40: ER 37 | S40: MID | T40: 24GE01S63 | W40: ER 37 | X40: 24GE01S63 | Y40: MID
B41: ON 25 | C41: ON 33M | D41: ON 12 | E41: ON 41 | R41: ER 59 | S41: B- | T41: 24GE03S11 | W41: ER 59 | X41: 24GE03S11 | Y41: B-
B42: 24GO01S01 | C42: 24GO01S31 | D42: 24GO00S90 | E42: 24GO01S43 | R42: HU 12 | S42: MID | T42: 24GH00S43 | W42: HU 12 | X42: 24GH00S43 | Y42: MID
B43: SRF | C43: 40M | D43: B10 | E43: 10M | R43: HU 37 | S43: B10 | T43: 24GH01S50 | W43: HU 37 | X43: 24GH01S50 | Y43: B10
B44: SU 03 | C44: SU 01M | D44: SU 04 | E44: SU 01M | R44: HU 45M | S44: 30M | T44: 24GH01S85 | W44: HU 45M | X44: 24GH01S85 | Y44: 30M
B45: 24GS00S41 | C45: 24GS00S06 | D45: 24GS00S70 | E45: 24GS00S03 | R45: MI 18M | S45: 50M | T45: 24GM00S47 | W45: MI 18M | X45: 24GM00S47 | Y45: 50M
B46: SRF | C46: B- | D46: B10 | E46: B- | R46: MI 27M | S46: SRF | T46: 24GM01S01 | W46: MI 27M | X46: 24GM01S01 | Y46: SRF
...

Sheet Station Depth Averages
E1: Station Depth (2008-2012)
A2: STATION_ID | B2: Mid Selection | C2: Average Mid Depth Rounded | D2: Average Mid Depth | E2: Average | F2: Standard Deviation | G2: N | H2: 2*Standard Error | K2: YEAR | L2: MONTH | M2: STATION_ID | N2: STN_DEPTH_m | O2: SAMPLE_ID | P2: ANL_CODE
A3: ER 09 | B3: MID | C3: =ROUND(D3,-1) -> 20 | D3: =E3/2 -> 24.815 | E3: 49.63 | F3: 1.2986228 | G3: 20 | H3: =2*(F3/SQRT(G3)) -> 0.58076175 | K3: 2008 | L3: April | M3: ER09 | N3: 50.6 | O3: 08GC20S81 | P3: Chlor-a
A4: ER 10 | B4: MID | C4: =ROUND(D4,-1) -> 20 | D4: =E4/2 -> 16.81 | E4: 33.62 | F4: 1.2853834 | G4: 20 | H4: =2*(F4/SQRT(G4)) -> 0.57484094 | K4: 2008 | L4: April | M4: ER09 | N4: 50.6 | O4: 08GC20S81 | P4: NO2+NO3 | S4: Values
A5: ER 15M | B5: 30M | C5: =ROUND(D5,-1) -> 30 | D5: =E5/2 -> 30.96 | E5: 61.92 | F5: 5.2771204 | G5: 20 | H5: =2*(F5/SQRT(G5)) -> 2.36 | K5: 2009 | L5: April | M5: ER09 | N5: 52.6 | O5: 09GC20S81 | P5: Chlor-a | R5: STATION_ID | S5: Average of STN_DEPTH_m | T5: StdDev of STN_DEPTH_m | U5: Count of STN_DEPTH_m
A6: ER 30 | B6: MID | C6: =ROUND(D6,-1) -> 10 | D6: =E6/2 -> 10.64 | E6: 21.28 | F6: 1.1989469 | G6: 20 | H6: =2*(F6/SQRT(G6)) -> 0.53618536 | K6: 2009 | L6: April | M6: ER09 | N6: 52.6 | O6: 09GC20S81 | P6: NO2+NO3 | R6: ER09 | S6: 49.63 | T6: 1.2986228 | U6: 20
A7: ER 31 | B7: MID | C7: =ROUND(D7,-1) -> 10 | D7: =E7/2 -> 11.12 | E7: 22.24 | F7: 0.51544564 | G7: 20 | H7: =2*(F7/SQRT(G7)) -> 0.2305143 | K7: 2010 | L7: April | M7: ER09 | N7: 50.1 | O7: 10GC20S81 | P7: Chlor-a | R7: ER10 | S7: 33.62 | T7: 1.2853834 | U7: 20
A8: ER 32 | B8: MID | C8: =ROUND(D8,-1) -> 10 | D8: =E8/2 -> 11.285 | E8: 22.57 | F8: 0.44497191 | G8: 20 | H8: =2*(F8/SQRT(G8)) -> 0.19899749 | K8: 2010 | L8: April | M8: ER09 | N8: 50.1 | O8: 10GC20S81 | P8: NO2+NO3 | R8: ER15M | S8: 61.92 | T8: 5.2771204 | U8: 20
A9: ER 36 | B9: MID | C9: =ROUND(D9,-1) -> 10 | D9: =E9/2 -> 11.675 | E9: 23.35 | F9: 0.4751731 | G9: 20 | H9: =2*(F9/SQRT(G9)) -> 0.21250387 | K9: 2011 | L9: April | M9: ER09 | N9: 49.2 | O9: 11GC20S81 | P9: Chlor-a | R9: ER30 | S9: 21.28 | T9: 1.1989469 | U9: 20
A10: ER 37 | B10: MID | C10: =ROUND(D10,-1) -> 10 | D10: =E10/2 -> 12.275 | E10: 24.55 | F10: 1.20547 | G10: 20 | H10: =2*(F10/SQRT(G10)) -> 0.53910257 | K10: 2011 | L10: April | M10: ER09 | N10: 49.2 | O10: 11GC20S81 | P10: NO2+NO3 | R10: ER31 | S10: 22.24 | T10: 0.51544564 | U10: 20
A11: ER 38 | B11: MID | C11: =ROUND(D11,-1) -> 10 | D11: =E11/2 -> 11.23 | E11: 22.46 | F11: 1.1080566 | G11: 20 | H11: =2*(F11/SQRT(G11)) -> 0.49553799 | K11: 2012 | L11: April | M11: ER09 | N11: 50.6 | O11: 12GC17S81 | P11: Chlor-a | R11: ER32 | S11: 22.57 | T11: 0.44497191 | U11: 20
A12: ER 42 | B12: MID | C12: =ROUND(D12,-1) -> 10 | D12: =E12/2 -> 11.2 | E12: 22.4 | F12: 0.49417661 | G12: 20 | H12: =2*(F12/SQRT(G12)) -> 0.2210025 | K12: 2012 | L12: April | M12: ER09 | N12: 50.6 | O12: 12GC17S81 | P12: NO2+NO3 | R12: ER36 | S12: 23.35 | T12: 0.4751731 | U12: 20
A13: ER 43 | B13: MID | C13: =ROUND(D13,-1) -> 10 | D13: =E13/2 -> 11.1 | E13: 22.2 | F13: 0.64726144 | G13: 20 | H13: =2*(F13/SQRT(G13)) -> 0.28946411 | K13: 2008 | L13: August | M13: ER09 | N13: 48.6 | O13: 08GC43S81 | P13: Chlor-a | R13: ER37 | S13: 24.55 | T13: 1.20547 | U13: 20
A14: ER 58 | B14: MID | C14: =ROUND(D14,-1) -> 0 | D14: =E14/2 -> 4.88 | E14: 9.76 | F14: 1.0535154 | G14: 20 | H14: =2*(F14/SQRT(G14)) -> 0.47114642 | K14: 2008 | L14: August | M14: ER09 | N14: 48.6 | O14: 08GC43S81 | P14: NO2+NO3 | R14: ER38 | S14: 22.46 | T14: 1.1080566 | U14: 20
A15: ER 59 | B15: MID | C15: =ROUND(D15,-1) -> 0 | D15: =E15/2 -> 4.025 | E15: 8.05 | F15: 0.17917942 | G15: 20 | H15: =2*(F15/SQRT(G15)) -> 0.080131471 | K15: 2009 | L15: August | M15: ER09 | N15: 48.6 | O15: 09GC46S81 | P15: Chlor-a | R15: ER42 | S15: 22.4 | T15: 0.49417661 | U15: 20
A16: ER 60 | B16: MID | C16: =ROUND(D16,-1) -> 0 | D16: =E16/2 -> 4.17 | E16: 8.34 | F16: 0.17888544 | G16: 20 | H16: =2*(F16/SQRT(G16)) -> 0.08 | K16: 2009 | L16: August | M16: ER09 | N16: 48.6 | O16: 09GC46S81 | P16: NO2+NO3 | R16: ER43 | S16: 22.2 | T16: 0.64726144 | U16: 20
A17: ER 61 | B17: MID | C17: =ROUND(D17,-1) -> 0 | D17: =E17/2 -> 4.54 | E17: 9.08 | F17: 0.29307804 | G17: 20 | H17: =2*(F17/SQRT(G17)) -> 0.13106848 | K17: 2010 | L17: August | M17: ER09 | N17: 48.6 | O17: 10GC43S81 | P17: Chlor-a | R17: ER58 | S17: 9.76 | T17: 1.0535154 | U17: 20
... A38: HU 93 | B38: MID | C38: =ROUND(D38,-1) -> 50 | D38: =E38/2 -> 45.155 | E38: 90.31 | F38: 0.7642678 | G38: 20 | H38: =2*(F38/SQRT(G38)) -> 0.34179095 | K38: 2010 | L38: August | M38: ER10 | N38: 33.1 | O38: 10GC44S01 | P38: NO2+NO3 | R38: HU53 | S38: 92.71 | T38: 1.0182028 | U38: 20
A39: HU 98b | K39: 2011 | L39: August | M39: ER10 | N39: 33.1 | O39: 11GC39S61 | P39: Chlor-a | R39: HU54M | S39: 129.29 | T39: 5.3473948 | U39: 20
A40: HU FE | B40: MID | C40: =ROUND(D40,-1) -> 60 | D40: =E40/2 -> 57.375 | E40: 114.75 | F40: 0.11677484 | G40: 12 | H40: =2*(F40/SQRT(G40)) -> 0.067419986 | K40: 2011 | L40: August | M40: ER10 | N40: 33.1 | O40: 11GC39S61 | P40: NO2+NO3 | R40: HU61 | S40: 120.18 | T40: 2.5751035 | U40: 20
A41: HU FO | B41: MID | C41: =ROUND(D41,-1) -> 20 | D41: =E41/2 -> 18.8375 | E41: 37.675 | F41: 0.41661904 | G41: 8 | H41: =2*(F41/SQRT(G41)) -> 0.29459415 | K41: 2012 | L41: August | M41: ER10 | N41: 33 | O41: 12GC51S21 | P41: Chlor-a | R41: HU93 | S41: 90.31 | T41: 0.7642678 | U41: 20
A42: MI 11 | B42: MID | C42: =ROUND(D42,-1) -> 60 | D42: =E42/2 -> 63.945 | E42: 127.89 | F42: 2.3112767 | G42: 20 | H42: =2*(F42/SQRT(G42)) -> 1.0336344 | K42: 2012 | L42: August | M42: ER10 | N42: 33 | O42: 12GC51S21 | P42: NO2+NO3 | R42: HUFE | S42: 114.75 | T42: 0.11677484 | U42: 12
A43: MI 17 | B43: MID | C43: =ROUND(D43,-1) -> 50 | D43: =E43/2 -> 50.78 | E43: 101.56 | F43: 0.72285982 | G43: 20 | H43: =2*(F43/SQRT(G43)) -> 0.32327274 | K43: 2008 | L43: April | M43: ER15M | N43: 64.2 | O43: 08GC20S41 | P43: Chlor-a | R43: HUFO | S43: 37.675 | T43: 0.41661904 | U43: 8
A44: MI 18M | B44: 100M | C44: =ROUND(D44,-1) -> 80 | D44: =E44/2 -> 80.447 | E44: 160.894 | F44: 0.5087901 | G44: 20 | H44: =2*(F44/SQRT(G44)) -> 0.22753785 | K44: 2008 | L44: April | M44: ER15M | N44: 64.2 | O44: 08GC20S41 | P44: NO2+NO3 | R44: MI11 | S44: 127.89 | T44: 2.3112767 | U44: 20
A45: MI 19 | B45: MID | C45: =ROUND(D45,-1) -> 50 | D45: =E45/2 -> 45.34 | E45: 90.68 | F45: 1.3500877 | G45: 20 | H45: =2*(F45/SQRT(G45)) -> 0.60377758 | K45: 2009 | L45: April | M45: ER15M | N45: 64.7 | O45: 09GC20S21 | P45: Chlor-a | R45: MI17 | S45: 101.56 | T45: 0.72285982 | U45: 20
A46: MI 23 | B46: MID | C46: =ROUND(D46,-1) -> 50 | D46: =E46/2 -> 46.24 | E46: 92.48 | F46: 0.84080162 | G46: 20 | H46: =2*(F46/SQRT(G46)) -> 0.37601792 | K46: 2009 | L46: April | M46: ER15M | N46: 64.7 | O46: 09GC20S21 | P46: NO2+NO3 | R46: MI18M | S46: 160.894 | T46: 0.5087901 | U46: 20
A47: MI 27M | B47: 50M | C47: =ROUND(D47,-1) -> 50 | D47: =E47/2 -> 52.685 | E47: 105.37 | F47: 1.798274 | G47: 20 | H47: =2*(F47/SQRT(G47)) -> 0.80421259 | K47: 2010 | L47: April | M47: ER15M | N47: 64.4 | O47: 10GC20S41 | P47: Chlor-a | R47: MI19 | S47: 90.68 | T47: 1.3500877 | U47: 20
A48: MI 32 | B48: MID | C48: =ROUND(D48,-1) -> 80 | D48: =E48/2 -> 82.24 | E48: 164.48 | F48: 0.68024763 | G48: 20 | H48: =2*(F48/SQRT(G48)) -> 0.30421599 | K48: 2010 | L48: April | M48: ER15M | N48: 64.4 | O48: 10GC20S41 | P48: NO2+NO3 | R48: MI23 | S48: 92.48 | T48: 0.84080162 | U48: 20
A49: MI 34 | B49: MID | C49: =ROUND(D49,-1) -> 80 | D49: =E49/2 -> 79.8 | E49: 159.6 | F49: 0.77595442 | G49: 20 | H49: =2*(F49/SQRT(G49)) -> 0.34701737 | K49: 2011 | L49: April | M49: ER15M | N49: 46.7 | O49: 11GC20S21 | P49: Chlor-a | R49: MI27M | S49: 105.37 | T49: 1.798274 | U49: 20
A50: MI 40 | B50: MID | C50: =ROUND(D50,-1) -> 90 | D50: =E50/2 -> 85.42 | E50: 170.84 | F50: 1.2873473 | G50: 20 | H50: =2*(F50/SQRT(G50)) -> 0.57571923 | K50: 2011 | L50: April | M50: ER15M | N50: 46.7 | O50: 11GC20S21 | P50: NO2+NO3 | R50: MI32 | S50: 164.48 | T50: 0.68024763 | U50: 20
A51: MI 41M | B51: 100M | C51: =ROUND(D51,-1) -> 130 | D51: =E51/2 -> 132.245 | E51: 264.49 | F51: 2.9588227 | G51: 20 | H51: =2*(F51/SQRT(G51)) -> 1.3232257 | K51: 2012 | L51: April | M51: ER15M | N51: 64.2 | O51: 12GC17S41 | P51: Chlor-a | R51: MI34 | S51: 159.6 | T51: 0.77595442 | U51: 20
A52: MI 47 | B52: MID | C52: =ROUND(D52,-1) -> 100 | D52: =E52/2 -> 97.16 | E52: 194.32 | F52: 1.1723122 | G52: 20 | H52: =2*(F52/SQRT(G52)) -> 0.52427393 | K52: 2012 | L52: April | M52: ER15M | N52: 64.2 | O52: 12GC17S41 | P52: NO2+NO3 | R52: MI40 | S52: 170.84 | T52: 1.2873473 | U52: 20
A53: MI 49b | K53: 2008 | L53: August | M53: ER15M | N53: 62.2 | O53: 08GC43S41 | P53: Chlor-a | R53: MI41M | S53: 264.49 | T53: 2.9588227 | U53: 20
A54: MI 50b | K54: 2008 | L54: August | M54: ER15M | N54: 62.2 | O54: 08GC43S41 | P54: NO2+NO3 | R54: MI47 | S54: 194.32 | T54: 1.1723122 | U54: 20
A55: MI FE | B55: MID | C55: =ROUND(D55,-1) -> 30 | D55: =E55/2 -> 33.725 | E55: 67.45 | F55: 0.79486992 | G55: 12 | H55: =2*(F55/SQRT(G55)) -> 0.45891836 | K55: 2009 | L55: August | M55: ER15M | N55: 63.2 | O55: 09GC46S21 | P55: Chlor-a | R55: MIFE | S55: 67.45 | T55: 0.79486992 | U55: 12
A56: MI FO | B56: MID | C56: =ROUND(D56,-1) -> 60 | D56: =E56/2 -> 60.5625 | E56: 121.125 | F56: 0.50920105 | G56: 8 | H56: =2*(F56/SQRT(G56)) -> 0.36005952 | K56: 2009 | L56: August | M56: ER15M | N56: 63.2 | O56: 09GC46S21 | P56: NO2+NO3 | R56: MIFO | S56: 121.125 | T56: 0.50920105 | U56: 8
A57: ON 12 | B57: MID | C57: =ROUND(D57,-1) -> 50 | D57: =E57/2 -> 53.735 | E57: 107.47 | F57: 1.9531621 | G57: 20 | H57: =2*(F57/SQRT(G57)) -> 0.87348064 | K57: 2010 | L57: August | M57: ER15M | N57: 63.2 | O57: 10GC43S41 | P57: Chlor-a | R57: ON12 | S57: 107.47 | T57: 1.9531621 | U57: 20
A58: ON 25 | B58: MID | C58: =ROUND(D58,-1) -> 70 | D58: =E58/2 -> 68.48 | E58: 136.96 | F58: 7.3061186 | G58: 20 | H58: =2*(F58/SQRT(G58)) -> 3.2673956 | K58: 2010 | L58: August | M58: ER15M | N58: 63.2 | O58: 10GC43S41 | P58: NO2+NO3 | R58: ON25 | S58: 136.96 | T58: 7.3061186 | U58: 20
A59: ON 33M | B59: 100M | C59: =ROUND(D59,-1) -> 70 | D59: =E59/2 -> 70.35 | E59: 140.7 | F59: 1.6026294 | G59: 20 | H59: =2*(F59/SQRT(G59)) -> 0.71671766 | K59: 2011 | L59: August | M59: ER15M | N59: 64.2 | O59: 11GC39S01 | P59: Chlor-a | R59: ON33M | S59: 140.7 | T59: 1.6026294 | U59: 20
A60: ON 41 | B60: MID | C60: =ROUND(D60,-1) -> 70 | D60: =E60/2 -> 65.875 | E60: 131.75 | F60: 1.8975053 | G60: 20 | H60: =2*(F60/SQRT(G60)) -> 0.84859016 | K60: 2011 | L60: August | M60: ER15M | N60: 64.2 | O60: 11GC39S01 | P60: NO2+NO3 | R60: ON41 | S60: 131.75 | T60: 1.8975053 | U60: 20
...

Sheet Bottle_Jug Count
E1: Cincinatti | F1: Freund | G1: Basco | H1: Nalgene | I1: SKS | L1: Nalgene | M1: Freund | N1: Sartorious | O1: Fisher | P1: Fisher | Q1: Whatman | R1: SKS
E2: Water | H2: Phyto | I2: Benthos | L2: Zoo | N2: water | O2: Chlorophyll | R2: Sediment
E3: 125 mL Bottle | F3: ½ Gallon Milk Jugs | G3: 4 L Cubitainers | H3: 1000 mL Phyto | I3: 1000mL Benthos | J3: 500 mL Benthos | K3: Lids for Benthos | L3: 500 mL Zooplank | M3: Caps | N3: 0.45 µm Filters | O3: 12mm Culture Tubes | P3: 16mm Culture Tubes | Q3: G/FF Filters | R3: 4 oz | S3: 6 oz | T3: 4 oz Lids | U3: 6 oz Lids
D4: All | E4: ='All Sample IDs'!I1 -> 1574 | F4: ='All Sample IDs'!J1 -> 383 | G4: ='All Sample IDs'!M1 -> 84 | H4: ='All Sample IDs'!Q1 -> 248 | I4: ='All Sample IDs'!R1 -> 9 | K4: =I4+J4 -> 9 | L4: ='All Sample IDs'!T1 -> 212 | M4: =SUM('All Sample IDs'!I1:J1) -> 1957 | N4: ='All Sample IDs'!D1 -> 467 | O4: ='All Sample IDs'!G2 -> 467 | P4: ='All Sample IDs'!G3 -> 467 | Q4: ='All Sample IDs'!G1 -> 934 | R4: ='All Sample IDs'!V1 -> 5 | S4: ='All Sample IDs'!W1 -> 5 | T4: =R4 -> 5 | U4: =S4 -> 5
D5: 0.05 | E5: =ROUNDUP(E4*0.05,0) -> 79 | F5: =ROUNDUP(F4*0.05,0) -> 20 | G5: =ROUNDUP(G4*0.05,0) -> 5 | H5: =ROUNDUP(H4*0.05,0) -> 13 | I5: =ROUNDUP(I4*0.05,0) -> 1 | J5: =ROUNDUP(J4*0.05,0) -> 0 | K5: =ROUNDUP(K4*0.05,0) -> 1 | L5: =ROUNDUP(L4*0.05,0) -> 11 | ... U5: =ROUNDUP(U4*0.05,0) -> 1
D6: TOTAL Needed For Survey | E6: =E5+E4 -> 1653 | F6: =F5+F4 -> 403 | G6: =G5+G4 -> 89 | H6: =H5+H4 -> 261 | I6: =I5+I4 -> 10 | J6: =J5+J4 -> 0 | K6: =K5+K4 -> 10 | L6: =L5+L4 -> 223 | ... U6: =U5+U4 -> 6

Sheet Benthos
A1: Basin | B1: Station ID | C1: Sample ID | D1: Depth Code | E1: QC Type | F1: Visit ID | G1: Survey ID
A2: S | B2: HU 98b | C2: 24GH02S96 | D2: Benthos | E2: RFS | F2: H98bA24 | G2: HU2411
A3: S | B3: HU 98b | C3: 24GH02D96 | D3: Benthos | E3: FD1 | F3: H98bA24 | G3: HU2411
A4: S | B4: HU 98b | C4: 24GH02T96 | D4: Benthos | E4: FD2 | F4: H98bA24 | G4: HU2411
A5: W | B5: ER 61 | C5: 24GE03S56 | D5: Benthos | E5: RFS | F5: E061A24 | G5: ER2411
A6: W | B6: ER 61 | C6: 24GE03D56 | D6: Benthos | E6: FD1 | F6: E061A24 | G6: ER2411
A7: W | B7: ER 61 | C7: 24GE03T56 | D7: Benthos | E7: FD2 | F7: E061A24 | G7: ER2411
A8: W | B8: ER 91M | C8: 24GE03S76 | D8: Benthos | E8: RFS | F8: E91MA24 | G8: ER2411
A9: W | B9: ER 91M | C9: 24GE03D76 | D9: Benthos | E9: FD1 | F9: E91MA24 | G9: ER2411
A10: W | B10: ER 91M | C10: 24GE03T76 | D10: Benthos | E10: FD2 | F10: E91MA24 | G10: ER2411

Sheet All Sample IDs
D1: =H4 -> 467 | E1: # of 0.45 Filters | F1: # of GF/F Filters | G1: =H4*2 -> 934 | I1: =(H4*3)+I4 -> 1574 | J1: =H4-K4 -> 383 | M1: =SUM(K4:P4) -> 84 | Q1: =Q4+S4 -> 248 | R1: =R4 -> 9 | T1: =T4 -> 212 | V1: =V4 -> 5 | W1: =W4 -> 5
B2: =492-84 -> 408 | F2: # of 13mm | G2: =H4 -> 467 | H2: 125 mL sample Bottles | J2: ½ Gallon Milk Jugs | K2: Cubitainers | Q2: 1000mL | T2: 500 mL | V2: 4 oz HDPE | W2: 6 oz Glass
F3: # of 16mm | G3: =H4 -> 467 | K3: Phyto | P3: =SUM(P6:P991) -> 29 | U3: DO
G4: # of Samples | H4: =SUM(H6:H976) -> 467 | I4: =SUM(I6:I976) -> 173 | J4: =SUM(J6:J976) -> 381 | K4: =SUM(K6:K976) -> 84 | Q4: =SUM(Q6:Q976) -> 136 | R4: =SUM(R6:R976) -> 9 | S4: =SUM(S6:S976) -> 112 | T4: =SUM(T6:T976) -> 212 | U4: =SUM(U6:U1020) -> 43 | V4: =SUM(V6:V976) -> 5 | W4: =SUM(W6:W976) -> 5 | X4: =SUM(X6:X976) -> 1651 | Y4: =SUM(Y6:Y976) -> 14 | AA4: =SUM(AA6:AA976)*3 -> 1401
A5: Basin | B5: Station ID | C5: Sample ID | D5: Depth Code | E5: QC Type | F5: Visit ID | G5: Survey ID | H5: Nutrients | I5: Metals Total | J5: Board | K5: Int,Comp | L5: susps | M5: tpp | N5: tpn | O5: poc | P5: particulate | Q5: Phyto Plankton | R5: Benthos | S5: Mysis | T5: Zoo Plankton | U5: DO | V5: Grain Size Analysis | W5: Sediment CNP | X5: Nutrients Bottle Count | Y5: DO QA
A6: S | B6: MI 11 | C6: 24GM00S01 | D6: SRF | E6: RFS | F6: M011A24 | G6: MI2411 | H6: =IF(OR(RIGHT(C6,1)="A",RIGHT(C6,1)="B",RIGHT(C6,1)="C",D6="Benthos",D6="Sediment",D6="Sediments",D6="D100",D6="D20",D6="Mysis",E6="FD1",E6="LD1"),"",1) -> 1 | I6: =IF(RIGHT(B6,1)="M",IF(AND(H6=1,E6="RFS",D6=INDEX('Station Depth Averages'!$A$3:$B$84,MATCH(B6,'Station Depth Averages'!$A$3:$A$84,0),2)),1,""),IF(AND(H6=1,OR(D6="SYN",D6="SRF",D6="MID")),1,IF(AND(H6=1,OR(E7="FDn",E7="LDn")),1,IF(AND(H6=1,OR(E6="FDn",E6="LDn")),1,"")))) -> 1 | J6: =IF(OR(D6="INT",D6="Benthos",D6="D100",D6="D20",E6="LDn",D6="mysis",D6="sediment",D6="sediments",OR(RIGHT(C6,1)="A",RIGHT(C6,1)="B",RIGHT(C6,1)="C",E6="FD1",E6="LD1")),"",1) -> 1 | K6: =IF(D6="INT",1,"") | L6: =IF(AND(LEFT(B6,1)="E",A6<>"E",RIGHT(B6,1)="M"),IF(AND(A6="w",D6="MID",E6="RFS"),1,IF(AND(A6="C",D6="5M",E6="RFS"),1,"")),IF(AND(RIGHT(B6,1)="M",D6="10M",E6="RFS"),1,"")) | M6: =IF(L6=1,1,"") | N6: =IF(M6=1,1,"") | O6: =IF(N6=1,1,"") | P6: =IF(O6=1,1,"") | Q6: =IF(AND(OR(D6="INT",D6="DCL"),OR(LEFT(B6,2)="SU",LEFT(B6,2)="HU",LEFT(B6,2)="MI",LEFT(B6,2)="CS",LEFT(B6,2)="ON")),2,IF(AND(OR(D6="INT",D6="DCL"),LEFT(B6,2)="ER"),1,"")) | R6: =IF(D6="benthos",1,"") | S6: =IF(D6="mysis",1,"") | T6: =IF(AND(OR(D6="d20",D6="d100"),LEFT(B6,2)="SU"),2,IF(OR(D6="D20",D6="d100"),1,"")) | U6: =IF(VLOOKUP(C6,'QA Table'!$Y$5:$Y$20,1,TRUE)=C6,1,0) -> 0 | V6: =IF(AND(D6="Sediment",RIGHT(C6,1)="8"),1,"") | W6: =IF(AND(D6="Sediment",RIGHT(C6,1)="9"),1,"") | X6: =IF(AND(H6=1,OR(LEFT(B6,1)="M",LEFT(B6,1)="E",LEFT(B6,1)="O",LEFT(B6,1)="C")),4,IF(AND(H6=1,OR(LEFT(B6,1)="H",LEFT(B6,1)="S")),3,"")) -> 4 | Y6: =IF(U6=1,1,IF(AND(E6="LD1",U5=1),1,IF(AND(E6="FD1",U4=1),1,0))) -> 0 | AA6: =IF(X6<>"",1,"") -> 1
A7: S | B7: MI 11 | C7: 24GM00D01 | D7: SRF | E7: FDn | F7: M011A24 | G7: MI2411 | H7: =IF(OR(RIGHT(C7,1)="A",RIGHT(C7,1)="B",RIGHT(C7,1)="C",D7="Benthos",D7="Sediment",D7="Sediments",D7="D100",D7="D20",D7="Mysis",E7="FD1",E7="LD1"),"",1) -> 1 | I7: =IF(RIGHT(B7,1)="M",IF(AND(H7=1,E7="RFS",D7=INDEX('Station Depth Averages'!$A$3:$B$84,MATCH(B7,'Station Depth Averages'!$A$3:$A$84,0),2)),1,""),IF(AND(H7=1,OR(D7="SYN",D7="SRF",D7="MID")),1,IF(AND(H7=1,OR(E8="FDn",E8="LDn")),1,IF(AND(H7=1,OR(E7="FDn",E7="LDn")),1,"")))) -> 1 | J7: =IF(OR(D7="INT",D7="Benthos",D7="D100",D7="D20",E7="LDn",D7="mysis",D7="sediment",D7="sediments",OR(RIGHT(C7,1)="A",RIGHT(C7,1)="B",RIGHT(C7,1)="C",E7="FD1",E7="LD1")),"",1) -> 1 | K7: =IF(D7="INT",1,"") | L7: =IF(AND(LEFT(B7,1)="E",A7<>"E",RIGHT(B7,1)="M"),IF(AND(A7="w",D7="MID",E7="RFS"),1,IF(AND(A7="C",D7="5M",E7="RFS"),1,"")),IF(AND(RIGHT(B7,1)="M",D7="10M",E7="RFS"),1,"")) | M7: =IF(L7=1,1,"") | N7: =IF(M7=1,1,"") | O7: =IF(N7=1,1,"") | P7: =IF(O7=1,1,"") | Q7: =IF(AND(OR(D7="INT",D7="DCL"),OR(LEFT(B7,2)="SU",LEFT(B7,2)="HU",LEFT(B7,2)="MI",LEFT(B7,2)="CS",LEFT(B7,2)="ON")),2,IF(AND(OR(D7="INT",D7="DCL"),LEFT(B7,2)="ER"),1,"")) | R7: =IF(D7="benthos",1,"") | S7: =IF(D7="mysis",1,"") | T7: =IF(AND(OR(D7="d20",D7="d100"),LEFT(B7,2)="SU"),2,IF(OR(D7="D20",D7="d100"),1,"")) | U7: =IF(VLOOKUP(C7,'QA Table'!$Y$5:$Y$20,1,TRUE)=C7,1,0) -> 0 | V7: =IF(AND(D7="Sediment",RIGHT(C7,1)="8"),1,"") | W7: =IF(AND(D7="Sediment",RIGHT(C7,1)="9"),1,"") | X7: =IF(AND(H7=1,OR(LEFT(B7,1)="M",LEFT(B7,1)="E",LEFT(B7,1)="O",LEFT(B7,1)="C")),4,IF(AND(H7=1,OR(LEFT(B7,1)="H",LEFT(B7,1)="S")),3,"")) -> 4 | Y7: =IF(U7=1,1,IF(AND(E7="LD1",U6=1),1,IF(AND(E7="FD1",U5=1),1,0))) -> 0 | AA7: =IF(X7<>"",1,"") -> 1
A8: S | B8: MI 11 | C8: 24GM00S0A | D8: 5M | E8: RFS | F8: M011A24 | G8: MI2411 | H8: =IF(OR(RIGHT(C8,1)="A",RIGHT(C8,1)="B",RIGHT(C8,1)="C",D8="Benthos",D8="Sediment",D8="Sediments",D8="D100",D8="D20",D8="Mysis",E8="FD1",E8="LD1"),"",1) | I8: =IF(RIGHT(B8,1)="M",IF(AND(H8=1,E8="RFS",D8=INDEX('Station Depth Averages'!$A$3:$B$84,MATCH(B8,'Station Depth Averages'!$A$3:$A$84,0),2)),1,""),IF(AND(H8=1,OR(D8="SYN",D8="SRF",D8="MID")),1,IF(AND(H8=1,OR(E9="FDn",E9="LDn")),1,IF(AND(H8=1,OR(E8="FDn",E8="LDn")),1,"")))) | J8: =IF(OR(D8="INT",D8="Benthos",D8="D100",D8="D20",E8="LDn",D8="mysis",D8="sediment",D8="sediments",OR(RIGHT(C8,1)="A",RIGHT(C8,1)="B",RIGHT(C8,1)="C",E8="FD1",E8="LD1")),"",1) | K8: =IF(D8="INT",1,"") | L8: =IF(AND(LEFT(B8,1)="E",A8<>"E",RIGHT(B8,1)="M"),IF(AND(A8="w",D8="MID",E8="RFS"),1,IF(AND(A8="C",D8="5M",E8="RFS"),1,"")),IF(AND(RIGHT(B8,1)="M",D8="10M",E8="RFS"),1,"")) | M8: =IF(L8=1,1,"") | N8: =IF(M8=1,1,"") | O8: =IF(N8=1,1,"") | P8: =IF(O8=1,1,"") | Q8: =IF(AND(OR(D8="INT",D8="DCL"),OR(LEFT(B8,2)="SU",LEFT(B8,2)="HU",LEFT(B8,2)="MI",LEFT(B8,2)="CS",LEFT(B8,2)="ON")),2,IF(AND(OR(D8="INT",D8="DCL"),LEFT(B8,2)="ER"),1,"")) | R8: =IF(D8="benthos",1,"") | S8: =IF(D8="mysis",1,"") | T8: =IF(AND(OR(D8="d20",D8="d100"),LEFT(B8,2)="SU"),2,IF(OR(D8="D20",D8="d100"),1,"")) | U8: =IF(VLOOKUP(C8,'QA Table'!$Y$5:$Y$20,1,TRUE)=C8,1,0) -> 0 | V8: =IF(AND(D8="Sediment",RIGHT(C8,1)="8"),1,"") | W8: =IF(AND(D8="Sediment",RIGHT(C8,1)="9"),1,"") | X8: =IF(AND(H8=1,OR(LEFT(B8,1)="M",LEFT(B8,1)="E",LEFT(B8,1)="O",LEFT(B8,1)="C")),4,IF(AND(H8=1,OR(LEFT(B8,1)="H",LEFT(B8,1)="S")),3,"")) | Y8: =IF(U8=1,1,IF(AND(E8="LD1",U7=1),1,IF(AND(E8="FD1",U6=1),1,0))) -> 0 | AA8: =IF(X8<>"",1,"")
A9: S | B9: MI 11 | C9: 24GM00S0B | D9: 10M | E9: RFS | F9: M011A24 | G9: MI2411 | H9: =IF(OR(RIGHT(C9,1)="A",RIGHT(C9,1)="B",RIGHT(C9,1)="C",D9="Benthos",D9="Sediment",D9="Sediments",D9="D100",D9="D20",D9="Mysis",E9="FD1",E9="LD1"),"",1) | I9: =IF(RIGHT(B9,1)="M",IF(AND(H9=1,E9="RFS",D9=INDEX('Station Depth Averages'!$A$3:$B$84,MATCH(B9,'Station Depth Averages'!$A$3:$A$84,0),2)),1,""),IF(AND(H9=1,OR(D9="SYN",D9="SRF",D9="MID")),1,IF(AND(H9=1,OR(E10="FDn",E10="LDn")),1,IF(AND(H9=1,OR(E9="FDn",E9="LDn")),1,"")))) | J9: =IF(OR(D9="INT",D9="Benthos",D9="D100",D9="D20",E9="LDn",D9="mysis",D9="sediment",D9="sediments",OR(RIGHT(C9,1)="A",RIGHT(C9,1)="B",RIGHT(C9,1)="C",E9="FD1",E9="LD1")),"",1) | K9: =IF(D9="INT",1,"") | L9: =IF(AND(LEFT(B9,1)="E",A9<>"E",RIGHT(B9,1)="M"),IF(AND(A9="w",D9="MID",E9="RFS"),1,IF(AND(A9="C",D9="5M",E9="RFS"),1,"")),IF(AND(RIGHT(B9,1)="M",D9="10M",E9="RFS"),1,"")) | M9: =IF(L9=1,1,"") | N9: =IF(M9=1,1,"") | O9: =IF(N9=1,1,"") | P9: =IF(O9=1,1,"") | Q9: =IF(AND(OR(D9="INT",D9="DCL"),OR(LEFT(B9,2)="SU",LEFT(B9,2)="HU",LEFT(B9,2)="MI",LEFT(B9,2)="CS",LEFT(B9,2)="ON")),2,IF(AND(OR(D9="INT",D9="DCL"),LEFT(B9,2)="ER"),1,"")) | R9: =IF(D9="benthos",1,"") | S9: =IF(D9="mysis",1,"") | T9: =IF(AND(OR(D9="d20",D9="d100"),LEFT(B9,2)="SU"),2,IF(OR(D9="D20",D9="d100"),1,"")) | U9: =IF(VLOOKUP(C9,'QA Table'!$Y$5:$Y$20,1,TRUE)=C9,1,0) -> 0 | V9: =IF(AND(D9="Sediment",RIGHT(C9,1)="8"),1,"") | W9: =IF(AND(D9="Sediment",RIGHT(C9,1)="9"),1,"") | X9: =IF(AND(H9=1,OR(LEFT(B9,1)="M",LEFT(B9,1)="E",LEFT(B9,1)="O",LEFT(B9,1)="C")),4,IF(AND(H9=1,OR(LEFT(B9,1)="H",LEFT(B9,1)="S")),3,"")) | Y9: =IF(U9=1,1,IF(AND(E9="LD1",U8=1),1,IF(AND(E9="FD1",U7=1),1,0))) -> 0 | AA9: =IF(X9<>"",1,"")
A10: S | B10: MI 11 | C10: 24GM00S0C | D10: 20M | E10: RFS | F10: M011A24 | G10: MI2411 | H10: =IF(OR(RIGHT(C10,1)="A",RIGHT(C10,1)="B",RIGHT(C10,1)="C",D10="Benthos",D10="Sediment",D10="Sediments",D10="D100",D10="D20",D10="Mysis",E10="FD1",E10="LD1"),"",1) | I10: =IF(RIGHT(B10,1)="M",IF(AND(H10=1,E10="RFS",D10=INDEX('Station Depth Averages'!$A$3:$B$84,MATCH(B10,'Station Depth Averages'!$A$3:$A$84,0),2)),1,""),IF(AND(H10=1,OR(D10="SYN",D10="SRF",D10="MID")),1,IF(AND(H10=1,OR(E11="FDn",E11="LDn")),1,IF(AND(H10=1,OR(E10="FDn",E10="LDn")),1,"")))) | J10: =IF(OR(D10="INT",D10="Benthos",D10="D100",D10="D20",E10="LDn",D10="mysis",D10="sediment",D10="sediments",OR(RIGHT(C10,1)="A",RIGHT(C10,1)="B",RIGHT(C10,1)="C",E10="FD1",E10="LD1")),"",1) | K10: =IF(D10="INT",1,"") | L10: =IF(AND(LEFT(B10,1)="E",A10<>"E",RIGHT(B10,1)="M"),IF(AND(A10="w",D10="MID",E10="RFS"),1,IF(AND(A10="C",D10="5M",E10="RFS"),1,"")),IF(AND(RIGHT(B10,1)="M",D10="10M",E10="RFS"),1,"")) | M10: =IF(L10=1,1,"") | N10: =IF(M10=1,1,"") | O10: =IF(N10=1,1,"") | P10: =IF(O10=1,1,"") | Q10: =IF(AND(OR(D10="INT",D10="DCL"),OR(LEFT(B10,2)="SU",LEFT(B10,2)="HU",LEFT(B10,2)="MI",LEFT(B10,2)="CS",LEFT(B10,2)="ON")),2,IF(AND(OR(D10="INT",D10="DCL"),LEFT(B10,2)="ER"),1,"")) | R10: =IF(D10="benthos",1,"") | S10: =IF(D10="mysis",1,"") | T10: =IF(AND(OR(D10="d20",D10="d100"),LEFT(B10,2)="SU"),2,IF(OR(D10="D20",D10="d100"),1,"")) | U10: =IF(VLOOKUP(C10,'QA Table'!$Y$5:$Y$20,1,TRUE)=C10,1,0) -> 0 | V10: =IF(AND(D10="Sediment",RIGHT(C10,1)="8"),1,"") | W10: =IF(AND(D10="Sediment",RIGHT(C10,1)="9"),1,"") | X10: =IF(AND(H10=1,OR(LEFT(B10,1)="M",LEFT(B10,1)="E",LEFT(B10,1)="O",LEFT(B10,1)="C")),4,IF(AND(H10=1,OR(LEFT(B10,1)="H",LEFT(B10,1)="S")),3,"")) | Y10: =IF(U10=1,1,IF(AND(E10="LD1",U9=1),1,IF(AND(E10="FD1",U8=1),1,0))) -> 0 | AA10: =IF(X10<>"",1,"")
A11: S | B11: MI 11 | C11: 24GM00S03 | D11: MID | E11: RFS | F11: M011A24 | G11: MI2411 | H11: =IF(OR(RIGHT(C11,1)="A",RIGHT(C11,1)="B",RIGHT(C11,1)="C",D11="Benthos",D11="Sediment",D11="Sediments",D11="D100",D11="D20",D11="Mysis",E11="FD1",E11="LD1"),"",1) -> 1 | I11: =IF(RIGHT(B11,1)="M",IF(AND(H11=1,E11="RFS",D11=INDEX('Station Depth Averages'!$A$3:$B$84,MATCH(B11,'Station Depth Averages'!$A$3:$A$84,0),2)),1,""),IF(AND(H11=1,OR(D11="SYN",D11="SRF",D11="MID")),1,IF(AND(H11=1,OR(E12="FDn",E12="LDn")),1,IF(AND(H11=1,OR(E11="FDn",E11="LDn")),1,"")))) -> 1 | J11: =IF(OR(D11="INT",D11="Benthos",D11="D100",D11="D20",E11="LDn",D11="mysis",D11="sediment",D11="sediments",OR(RIGHT(C11,1)="A",RIGHT(C11,1)="B",RIGHT(C11,1)="C",E11="FD1",E11="LD1")),"",1) -> 1 | K11: =IF(D11="INT",1,"") | L11: =IF(AND(LEFT(B11,1)="E",A11<>"E",RIGHT(B11,1)="M"),IF(AND(A11="w",D11="MID",E11="RFS"),1,IF(AND(A11="C",D11="5M",E11="RFS"),1,"")),IF(AND(RIGHT(B11,1)="M",D11="10M",E11="RFS"),1,"")) | M11: =IF(L11=1,1,"") | N11: =IF(M11=1,1,"") | O11: =IF(N11=1,1,"") | P11: =IF(O11=1,1,"") | Q11: =IF(AND(OR(D11="INT",D11="DCL"),OR(LEFT(B11,2)="SU",LEFT(B11,2)="HU",LEFT(B11,2)="MI",LEFT(B11,2)="CS",LEFT(B11,2)="ON")),2,IF(AND(OR(D11="INT",D11="DCL"),LEFT(B11,2)="ER"),1,"")) | R11: =IF(D11="benthos",1,"") | S11: =IF(D11="mysis",1,"") | T11: =IF(AND(OR(D11="d20",D11="d100"),LEFT(B11,2)="SU"),2,IF(OR(D11="D20",D11="d100"),1,"")) | U11: =IF(VLOOKUP(C11,'QA Table'!$Y$5:$Y$20,1,TRUE)=C11,1,0) -> 0 | V11: =IF(AND(D11="Sediment",RIGHT(C11,1)="8"),1,"") | W11: =IF(AND(D11="Sediment",RIGHT(C11,1)="9"),1,"") | X11: =IF(AND(H11=1,OR(LEFT(B11,1)="M",LEFT(B11,1)="E",LEFT(B11,1)="O",LEFT(B11,1)="C")),4,IF(AND(H11=1,OR(LEFT(B11,1)="H",LEFT(B11,1)="S")),3,"")) -> 4 | Y11: =IF(U11=1,1,IF(AND(E11="LD1",U10=1),1,IF(AND(E11="FD1",U9=1),1,0))) -> 0 | AA11: =IF(X11<>"",1,"") -> 1
A12: S | B12: MI 11 | C12: 24GM00S10 | D12: B10 | E12: RFS | F12: M011A24 | G12: MI2411 | H12: =IF(OR(RIGHT(C12,1)="A",RIGHT(C12,1)="B",RIGHT(C12,1)="C",D12="Benthos",D12="Sediment",D12="Sediments",D12="D100",D12="D20",D12="Mysis",E12="FD1",E12="LD1"),"",1) -> 1 | I12: =IF(RIGHT(B12,1)="M",IF(AND(H12=1,E12="RFS",D12=INDEX('Station Depth Averages'!$A$3:$B$84,MATCH(B12,'Station Depth Averages'!$A$3:$A$84,0),2)),1,""),IF(AND(H12=1,OR(D12="SYN",D12="SRF",D12="MID")),1,IF(AND(H12=1,OR(E13="FDn",E13="LDn")),1,IF(AND(H12=1,OR(E12="FDn",E12="LDn")),1,"")))) | J12: =IF(OR(D12="INT",D12="Benthos",D12="D100",D12="D20",E12="LDn",D12="mysis",D12="sediment",D12="sediments",OR(RIGHT(C12,1)="A",RIGHT(C12,1)="B",RIGHT(C12,1)="C",E12="FD1",E12="LD1")),"",1) -> 1 | K12: =IF(D12="INT",1,"") | L12: =IF(AND(LEFT(B12,1)="E",A12<>"E",RIGHT(B12,1)="M"),IF(AND(A12="w",D12="MID",E12="RFS"),1,IF(AND(A12="C",D12="5M",E12="RFS"),1,"")),IF(AND(RIGHT(B12,1)="M",D12="10M",E12="RFS"),1,"")) | M12: =IF(L12=1,1,"") | N12: =IF(M12=1,1,"") | O12: =IF(N12=1,1,"") | P12: =IF(O12=1,1,"") | Q12: =IF(AND(OR(D12="INT",D12="DCL"),OR(LEFT(B12,2)="SU",LEFT(B12,2)="HU",LEFT(B12,2)="MI",LEFT(B12,2)="CS",LEFT(B12,2)="ON")),2,IF(AND(OR(D12="INT",D12="DCL"),LEFT(B12,2)="ER"),1,"")) | R12: =IF(D12="benthos",1,"") | S12: =IF(D12="mysis",1,"") | T12: =IF(AND(OR(D12="d20",D12="d100"),LEFT(B12,2)="SU"),2,IF(OR(D12="D20",D12="d100"),1,"")) | U12: =IF(VLOOKUP(C12,'QA Table'!$Y$5:$Y$20,1,TRUE)=C12,1,0) -> 0 | V12: =IF(AND(D12="Sediment",RIGHT(C12,1)="8"),1,"") | W12: =IF(AND(D12="Sediment",RIGHT(C12,1)="9"),1,"") | X12: =IF(AND(H12=1,OR(LEFT(B12,1)="M",LEFT(B12,1)="E",LEFT(B12,1)="O",LEFT(B12,1)="C")),4,IF(AND(H12=1,OR(LEFT(B12,1)="H",LEFT(B12,1)="S")),3,"")) -> 4 | Y12: =IF(U12=1,1,IF(AND(E12="LD1",U11=1),1,IF(AND(E12="FD1",U10=1),1,0))) -> 0 | AA12: =IF(X12<>"",1,"") -> 1
A13: S | B13: MI 11 | C13: 24GM00S11 | D13: B- | E13: RFS | F13: M011A24 | G13: MI2411 | H13: =IF(OR(RIGHT(C13,1)="A",RIGHT(C13,1)="B",RIGHT(C13,1)="C",D13="Benthos",D13="Sediment",D13="Sediments",D13="D100",D13="D20",D13="Mysis",E13="FD1",E13="LD1"),"",1) -> 1 | I13: =IF(RIGHT(B13,1)="M",IF(AND(H13=1,E13="RFS",D13=INDEX('Station Depth Averages'!$A$3:$B$84,MATCH(B13,'Station Depth Averages'!$A$3:$A$84,0),2)),1,""),IF(AND(H13=1,OR(D13="SYN",D13="SRF",D13="MID")),1,IF(AND(H13=1,OR(E14="FDn",E14="LDn")),1,IF(AND(H13=1,OR(E13="FDn",E13="LDn")),1,"")))) | J13: =IF(OR(D13="INT",D13="Benthos",D13="D100",D13="D20",E13="LDn",D13="mysis",D13="sediment",D13="sediments",OR(RIGHT(C13,1)="A",RIGHT(C13,1)="B",RIGHT(C13,1)="C",E13="FD1",E13="LD1")),"",1) -> 1 | K13: =IF(D13="INT",1,"") | L13: =IF(AND(LEFT(B13,1)="E",A13<>"E",RIGHT(B13,1)="M"),IF(AND(A13="w",D13="MID",E13="RFS"),1,IF(AND(A13="C",D13="5M",E13="RFS"),1,"")),IF(AND(RIGHT(B13,1)="M",D13="10M",E13="RFS"),1,"")) | M13: =IF(L13=1,1,"") | N13: =IF(M13=1,1,"") | O13: =IF(N13=1,1,"") | P13: =IF(O13=1,1,"") | Q13: =IF(AND(OR(D13="INT",D13="DCL"),OR(LEFT(B13,2)="SU",LEFT(B13,2)="HU",LEFT(B13,2)="MI",LEFT(B13,2)="CS",LEFT(B13,2)="ON")),2,IF(AND(OR(D13="INT",D13="DCL"),LEFT(B13,2)="ER"),1,"")) | R13: =IF(D13="benthos",1,"") | S13: =IF(D13="mysis",1,"") | T13: =IF(AND(OR(D13="d20",D13="d100"),LEFT(B13,2)="SU"),2,IF(OR(D13="D20",D13="d100"),1,"")) | U13: =IF(VLOOKUP(C13,'QA Table'!$Y$5:$Y$20,1,TRUE)=C13,1,0) -> 0 | V13: =IF(AND(D13="Sediment",RIGHT(C13,1)="8"),1,"") | W13: =IF(AND(D13="Sediment",RIGHT(C13,1)="9"),1,"") | X13: =IF(AND(H13=1,OR(LEFT(B13,1)="M",LEFT(B13,1)="E",LEFT(B13,1)="O",LEFT(B13,1)="C")),4,IF(AND(H13=1,OR(LEFT(B13,1)="H",LEFT(B13,1)="S")),3,"")) -> 4 | Y13: =IF(U13=1,1,IF(AND(E13="LD1",U12=1),1,IF(AND(E13="FD1",U11=1),1,0))) -> 0 | AA13: =IF(X13<>"",1,"") -> 1
A14: S | B14: MI 11 | C14: 24GM00I12 | D14: INT | E14: RFS | F14: M011A24 | G14: MI2411 | H14: =IF(OR(RIGHT(C14,1)="A",RIGHT(C14,1)="B",RIGHT(C14,1)="C",D14="Benthos",D14="Sediment",D14="Sediments",D14="D100",D14="D20",D14="Mysis",E14="FD1",E14="LD1"),"",1) -> 1 | I14: =IF(RIGHT(B14,1)="M",IF(AND(H14=1,E14="RFS",D14=INDEX('Station Depth Averages'!$A$3:$B$84,MATCH(B14,'Station Depth Averages'!$A$3:$A$84,0),2)),1,""),IF(AND(H14=1,OR(D14="SYN",D14="SRF",D14="MID")),1,IF(AND(H14=1,OR(E15="FDn",E15="LDn")),1,IF(AND(H14=1,OR(E14="FDn",E14="LDn")),1,"")))) | J14: =IF(OR(D14="INT",D14="Benthos",D14="D100",D14="D20",E14="LDn",D14="mysis",D14="sediment",D14="sediments",OR(RIGHT(C14,1)="A",RIGHT(C14,1)="B",RIGHT(C14,1)="C",E14="FD1",E14="LD1")),"",1) | K14: =IF(D14="INT",1,"") -> 1 | L14: =IF(AND(LEFT(B14,1)="E",A14<>"E",RIGHT(B14,1)="M"),IF(AND(A14="w",D14="MID",E14="RFS"),1,IF(AND(A14="C",D14="5M",E14="RFS"),1,"")),IF(AND(RIGHT(B14,1)="M",D14="10M",E14="RFS"),1,"")) | M14: =IF(L14=1,1,"") | N14: =IF(M14=1,1,"") | O14: =IF(N14=1,1,"") | P14: =IF(O14=1,1,"") | Q14: =IF(AND(OR(D14="INT",D14="DCL"),OR(LEFT(B14,2)="SU",LEFT(B14,2)="HU",LEFT(B14,2)="MI",LEFT(B14,2)="CS",LEFT(B14,2)="ON")),2,IF(AND(OR(D14="INT",D14="DCL"),LEFT(B14,2)="ER"),1,"")) -> 2 | R14: =IF(D14="benthos",1,"") | S14: =IF(D14="mysis",1,"") | T14: =IF(AND(OR(D14="d20",D14="d100"),LEFT(B14,2)="SU"),2,IF(OR(D14="D20",D14="d100"),1,"")) | U14: =IF(VLOOKUP(C14,'QA Table'!$Y$5:$Y$20,1,TRUE)=C14,1,0) -> 0 | V14: =IF(AND(D14="Sediment",RIGHT(C14,1)="8"),1,"") | W14: =IF(AND(D14="Sediment",RIGHT(C14,1)="9"),1,"") | X14: =IF(AND(H14=1,OR(LEFT(B14,1)="M",LEFT(B14,1)="E",LEFT(B14,1)="O",LEFT(B14,1)="C")),4,IF(AND(H14=1,OR(LEFT(B14,1)="H",LEFT(B14,1)="S")),3,"")) -> 4 | Y14: =IF(U14=1,1,IF(AND(E14="LD1",U13=1),1,IF(AND(E14="FD1",U12=1),1,0))) -> 0 | AA14: =IF(X14<>"",1,"") -> 1
A15: S | B15: MI 11 | C15: 24GM00I13 | D15: D100 | E15: RFS | F15: M011A24 | G15: MI2411 | H15: =IF(OR(RIGHT(C15,1)="A",RIGHT(C15,1)="B",RIGHT(C15,1)="C",D15="Benthos",D15="Sediment",D15="Sediments",D15="D100",D15="D20",D15="Mysis",E15="FD1",E15="LD1"),"",1) | I15: =IF(RIGHT(B15,1)="M",IF(AND(H15=1,E15="RFS",D15=INDEX('Station Depth Averages'!$A$3:$B$84,MATCH(B15,'Station Depth Averages'!$A$3:$A$84,0),2)),1,""),IF(AND(H15=1,OR(D15="SYN",D15="SRF",D15="MID")),1,IF(AND(H15=1,OR(E16="FDn",E16="LDn")),1,IF(AND(H15=1,OR(E15="FDn",E15="LDn")),1,"")))) | J15: =IF(OR(D15="INT",D15="Benthos",D15="D100",D15="D20",E15="LDn",D15="mysis",D15="sediment",D15="sediments",OR(RIGHT(C15,1)="A",RIGHT(C15,1)="B",RIGHT(C15,1)="C",E15="FD1",E15="LD1")),"",1) | K15: =IF(D15="INT",1,"") | L15: =IF(AND(LEFT(B15,1)="E",A15<>"E",RIGHT(B15,1)="M"),IF(AND(A15="w",D15="MID",E15="RFS"),1,IF(AND(A15="C",D15="5M",E15="RFS"),1,"")),IF(AND(RIGHT(B15,1)="M",D15="10M",E15="RFS"),1,"")) | M15: =IF(L15=1,1,"") | N15: =IF(M15=1,1,"") | O15: =IF(N15=1,1,"") | P15: =IF(O15=1,1,"") | Q15: =IF(AND(OR(D15="INT",D15="DCL"),OR(LEFT(B15,2)="SU",LEFT(B15,2)="HU",LEFT(B15,2)="MI",LEFT(B15,2)="CS",LEFT(B15,2)="ON")),2,IF(AND(OR(D15="INT",D15="DCL"),LEFT(B15,2)="ER"),1,"")) | R15: =IF(D15="benthos",1,"") | S15: =IF(D15="mysis",1,"") | T15: =IF(AND(OR(D15="d20",D15="d100"),LEFT(B15,2)="SU"),2,IF(OR(D15="D20",D15="d100"),1,"")) -> 1 | U15: =IF(VLOOKUP(C15,'QA Table'!$Y$5:$Y$20,1,TRUE)=C15,1,0) -> 0 | V15: =IF(AND(D15="Sediment",RIGHT(C15,1)="8"),1,"") | W15: =IF(AND(D15="Sediment",RIGHT(C15,1)="9"),1,"") | X15: =IF(AND(H15=1,OR(LEFT(B15,1)="M",LEFT(B15,1)="E",LEFT(B15,1)="O",LEFT(B15,1)="C")),4,IF(AND(H15=1,OR(LEFT(B15,1)="H",LEFT(B15,1)="S")),3,"")) | Y15: =IF(U15=1,1,IF(AND(E15="LD1",U14=1),1,IF(AND(E15="FD1",U13=1),1,0))) -> 0 | AA15: =IF(X15<>"",1,"")
A16: S | B16: MI 11 | C16: 24GM00I14 | D16: D20 | E16: RFS | F16: M011A24 | G16: MI2411 | H16: =IF(OR(RIGHT(C16,1)="A",RIGHT(C16,1)="B",RIGHT(C16,1)="C",D16="Benthos",D16="Sediment",D16="Sediments",D16="D100",D16="D20",D16="Mysis",E16="FD1",E16="LD1"),"",1) | I16: =IF(RIGHT(B16,1)="M",IF(AND(H16=1,E16="RFS",D16=INDEX('Station Depth Averages'!$A$3:$B$84,MATCH(B16,'Station Depth Averages'!$A$3:$A$84,0),2)),1,""),IF(AND(H16=1,OR(D16="SYN",D16="SRF",D16="MID")),1,IF(AND(H16=1,OR(E17="FDn",E17="LDn")),1,IF(AND(H16=1,OR(E16="FDn",E16="LDn")),1,"")))) | J16: =IF(OR(D16="INT",D16="Benthos",D16="D100",D16="D20",E16="LDn",D16="mysis",D16="sediment",D16="sediments",OR(RIGHT(C16,1)="A",RIGHT(C16,1)="B",RIGHT(C16,1)="C",E16="FD1",E16="LD1")),"",1) | K16: =IF(D16="INT",1,"") | L16: =IF(AND(LEFT(B16,1)="E",A16<>"E",RIGHT(B16,1)="M"),IF(AND(A16="w",D16="MID",E16="RFS"),1,IF(AND(A16="C",D16="5M",E16="RFS"),1,"")),IF(AND(RIGHT(B16,1)="M",D16="10M",E16="RFS"),1,"")) | M16: =IF(L16=1,1,"") | N16: =IF(M16=1,1,"") | O16: =IF(N16=1,1,"") | P16: =IF(O16=1,1,"") | Q16: =IF(AND(OR(D16="INT",D16="DCL"),OR(LEFT(B16,2)="SU",LEFT(B16,2)="HU",LEFT(B16,2)="MI",LEFT(B16,2)="CS",LEFT(B16,2)="ON")),2,IF(AND(OR(D16="INT",D16="DCL"),LEFT(B16,2)="ER"),1,"")) | R16: =IF(D16="benthos",1,"") | S16: =IF(D16="mysis",1,"") | T16: =IF(AND(OR(D16="d20",D16="d100"),LEFT(B16,2)="SU"),2,IF(OR(D16="D20",D16="d100"),1,"")) -> 1 | U16: =IF(VLOOKUP(C16,'QA Table'!$Y$5:$Y$20,1,TRUE)=C16,1,0) -> 0 | V16: =IF(AND(D16="Sediment",RIGHT(C16,1)="8"),1,"") | W16: =IF(AND(D16="Sediment",RIGHT(C16,1)="9"),1,"") | X16: =IF(AND(H16=1,OR(LEFT(B16,1)="M",LEFT(B16,1)="E",LEFT(B16,1)="O",LEFT(B16,1)="C")),4,IF(AND(H16=1,OR(LEFT(B16,1)="H",LEFT(B16,1)="S")),3,"")) | Y16: =IF(U16=1,1,IF(AND(E16="LD1",U15=1),1,IF(AND(E16="FD1",U14=1),1,0))) -> 0 | AA16: =IF(X16<>"",1,"")
A17: S | B17: MI 11 | C17: 24GM00S17 | D17: Mysis | E17: RFS | F17: M011A24 | G17: MI2411 | H17: =IF(OR(RIGHT(C17,1)="A",RIGHT(C17,1)="B",RIGHT(C17,1)="C",D17="Benthos",D17="Sediment",D17="Sediments",D17="D100",D17="D20",D17="Mysis",E17="FD1",E17="LD1"),"",1) | I17: =IF(RIGHT(B17,1)="M",IF(AND(H17=1,E17="RFS",D17=INDEX('Station Depth Averages'!$A$3:$B$84,MATCH(B17,'Station Depth Averages'!$A$3:$A$84,0),2)),1,""),IF(AND(H17=1,OR(D17="SYN",D17="SRF",D17="MID")),1,IF(AND(H17=1,OR(E18="FDn",E18="LDn")),1,IF(AND(H17=1,OR(E17="FDn",E17="LDn")),1,"")))) | J17: =IF(OR(D17="INT",D17="Benthos",D17="D100",D17="D20",E17="LDn",D17="mysis",D17="sediment",D17="sediments",OR(RIGHT(C17,1)="A",RIGHT(C17,1)="B",RIGHT(C17,1)="C",E17="FD1",E17="LD1")),"",1) | K17: =IF(D17="INT",1,"") | L17: =IF(AND(LEFT(B17,1)="E",A17<>"E",RIGHT(B17,1)="M"),IF(AND(A17="w",D17="MID",E17="RFS"),1,IF(AND(A17="C",D17="5M",E17="RFS"),1,"")),IF(AND(RIGHT(B17,1)="M",D17="10M",E17="RFS"),1,"")) | M17: =IF(L17=1,1,"") | N17: =IF(M17=1,1,"") | O17: =IF(N17=1,1,"") | P17: =IF(O17=1,1,"") | Q17: =IF(AND(OR(D17="INT",D17="DCL"),OR(LEFT(B17,2)="SU",LEFT(B17,2)="HU",LEFT(B17,2)="MI",LEFT(B17,2)="CS",LEFT(B17,2)="ON")),2,IF(AND(OR(D17="INT",D17="DCL"),LEFT(B17,2)="ER"),1,"")) | R17: =IF(D17="benthos",1,"") | S17: =IF(D17="mysis",1,"") -> 1 | T17: =IF(AND(OR(D17="d20",D17="d100"),LEFT(B17,2)="SU"),2,IF(OR(D17="D20",D17="d100"),1,"")) | U17: =IF(VLOOKUP(C17,'QA Table'!$Y$5:$Y$20,1,TRUE)=C17,1,0) -> 0 | V17: =IF(AND(D17="Sediment",RIGHT(C17,1)="8"),1,"") | W17: =IF(AND(D17="Sediment",RIGHT(C17,1)="9"),1,"") | X17: =IF(AND(H17=1,OR(LEFT(B17,1)="M",LEFT(B17,1)="E",LEFT(B17,1)="O",LEFT(B17,1)="C")),4,IF(AND(H17=1,OR(LEFT(B17,1)="H",LEFT(B17,1)="S")),3,"")) | Y17: =IF(U17=1,1,IF(AND(E17="LD1",U16=1),1,IF(AND(E17="FD1",U15=1),1,0))) -> 0 | AA17: =IF(X17<>"",1,"")
... A904: W | B904: SU 19 | C904: 24GS03D77 | D904: Mysis | E904: FD1 | F904: S019A24 | G904: SU2411 | H904: =IF(OR(RIGHT(C904,1)="A",RIGHT(C904,1)="B",RIGHT(C904,1)="C",D904="Benthos",D904="Sediment",D904="Sediments",D904="D100",D904="D20",D904="Mysis",E904="FD1",E904="LD1"),"",1) | I904: =IF(RIGHT(B904,1)="M",IF(AND(H904=1,E904="RFS",D904=INDEX('Station Depth Averages'!$A$3:$B$84,MATCH(B904,'Station Depth Averages'!$A$3:$A$84,0),2)),1,""),IF(AND(H904=1,OR(D904="SYN",D904="SRF",D904="MID")),1,IF(AND(H904=1,OR(E905="FDn",E905="LDn")),1,IF(AND(H904=1,OR(E904="FDn",E904="LDn")),1,"")))) | J904: =IF(OR(D904="INT",D904="Benthos",D904="D100",D904="D20",E904="LDn",D904="mysis",D904="sediment",D904="sediments",OR(RIGHT(C904,1)="A",RIGHT(C904,1)="B",RIGHT(C904,1)="C",E904="FD1",E904="LD1")),"",1) | K904: =IF(D904="INT",1,"") | L904: =IF(AND(LEFT(B904,1)="E",A904<>"E",RIGHT(B904,1)="M"),IF(AND(A904="w",D904="MID",E904="RFS"),1,IF(AND(A904="C",D904="5M",E904="RFS"),1,"")),IF(AND(RIGHT(B904,1)="M",D904="10M",E904="RFS"),1,"")) | M904: =IF(L904=1,1,"") | N904: =IF(M904=1,1,"") | O904: =IF(N904=1,1,"") | P904: =IF(O904=1,1,"") | Q904: =IF(AND(OR(D904="INT",D904="DCL"),OR(LEFT(B904,2)="SU",LEFT(B904,2)="HU",LEFT(B904,2)="MI",LEFT(B904,2)="CS",LEFT(B904,2)="ON")),2,IF(AND(OR(D904="INT",D904="DCL"),LEFT(B904,2)="ER"),1,"")) | R904: =IF(D904="benthos",1,"") | S904: =IF(D904="mysis",1,"") -> 1 | T904: =IF(AND(OR(D904="d20",D904="d100"),LEFT(B904,2)="SU"),2,IF(OR(D904="D20",D904="d100"),1,"")) | U904: =IF(VLOOKUP(C904,'QA Table'!$Y$5:$Y$20,1,TRUE)=C904,1,0) -> 0 | V904: =IF(AND(D904="Sediment",RIGHT(C904,1)="8"),1,"") | W904: =IF(AND(D904="Sediment",RIGHT(C904,1)="9"),1,"") | X904: =IF(AND(H904=1,OR(LEFT(B904,1)="M",LEFT(B904,1)="E",LEFT(B904,1)="O",LEFT(B904,1)="C")),4,IF(AND(H904=1,OR(LEFT(B904,1)="H",LEFT(B904,1)="S")),3,"")) | Y904: =IF(U904=1,1,IF(AND(E904="LD1",U903=1),1,IF(AND(E904="FD1",U902=1),1,0))) -> 0 | AA904: =IF(X904<>"",1,"")
A905: NS | B905: ECSER932n | C905: 24GE04S01 | D905: SRF | E905: RFS | F905: ECSER932nA24 | G905: ER2411 | J905: 1 | K905: =IF(D905="INT",1,"") | L905: =IF(AND(LEFT(B905,1)="E",A905<>"E",RIGHT(B905,1)="M"),IF(AND(A905="w",D905="MID",E905="RFS"),1,IF(AND(A905="C",D905="5M",E905="RFS"),1,"")),IF(AND(RIGHT(B905,1)="M",D905="10M",E905="RFS"),1,"")) | M905: =IF(L905=1,1,"") | N905: =IF(M905=1,1,"") | O905: =IF(N905=1,1,"") | P905: =IF(O905=1,1,"") | Q905: =IF(AND(OR(D905="INT",D905="DCL"),OR(LEFT(B905,2)="SU",LEFT(B905,2)="HU",LEFT(B905,2)="MI",LEFT(B905,2)="CS",LEFT(B905,2)="ON")),2,IF(AND(OR(D905="INT",D905="DCL"),LEFT(B905,2)="ER"),1,"")) | R905: =IF(D905="benthos",1,"") | S905: =IF(D905="mysis",1,"") | T905: =IF(AND(OR(D905="d20",D905="d100"),LEFT(B905,2)="SU"),2,IF(OR(D905="D20",D905="d100"),1,"")) | U905: =IF(VLOOKUP(C905,'QA Table'!$Y$5:$Y$20,1,TRUE)=C905,1,0) -> 0 | V905: =IF(AND(D905="Sediment",RIGHT(C905,1)="8"),1,"") | W905: =IF(AND(D905="Sediment",RIGHT(C905,1)="9"),1,"") | X905: =IF(AND(H905=1,OR(LEFT(B905,1)="M",LEFT(B905,1)="E",LEFT(B905,1)="O",LEFT(B905,1)="C")),4,IF(AND(H905=1,OR(LEFT(B905,1)="H",LEFT(B905,1)="S")),3,"")) | Y905: =IF(U905=1,1,IF(AND(E905="LD1",U904=1),1,IF(AND(E905="FD1",U903=1),1,0))) -> 0 | AA905: =IF(X905<>"",1,"")
A906: NS | B906: ECSER932n | C906: 24GE04S0A | D906: 5M | E906: RFS | F906: ECSER932nA24 | G906: ER2411 | K906: =IF(D906="INT",1,"") | L906: =IF(AND(LEFT(B906,1)="E",A906<>"E",RIGHT(B906,1)="M"),IF(AND(A906="w",D906="MID",E906="RFS"),1,IF(AND(A906="C",D906="5M",E906="RFS"),1,"")),IF(AND(RIGHT(B906,1)="M",D906="10M",E906="RFS"),1,"")) | M906: =IF(L906=1,1,"") | N906: =IF(M906=1,1,"") | O906: =IF(N906=1,1,"") | P906: =IF(O906=1,1,"") | Q906: =IF(AND(OR(D906="INT",D906="DCL"),OR(LEFT(B906,2)="SU",LEFT(B906,2)="HU",LEFT(B906,2)="MI",LEFT(B906,2)="CS",LEFT(B906,2)="ON")),2,IF(AND(OR(D906="INT",D906="DCL"),LEFT(B906,2)="ER"),1,"")) | R906: =IF(D906="benthos",1,"") | S906: =IF(D906="mysis",1,"") | T906: =IF(AND(OR(D906="d20",D906="d100"),LEFT(B906,2)="SU"),2,IF(OR(D906="D20",D906="d100"),1,"")) | U906: =IF(VLOOKUP(C906,'QA Table'!$Y$5:$Y$20,1,TRUE)=C906,1,0) -> 0 | V906: =IF(AND(D906="Sediment",RIGHT(C906,1)="8"),1,"") | W906: =IF(AND(D906="Sediment",RIGHT(C906,1)="9"),1,"") | X906: =IF(AND(H906=1,OR(LEFT(B906,1)="M",LEFT(B906,1)="E",LEFT(B906,1)="O",LEFT(B906,1)="C")),4,IF(AND(H906=1,OR(LEFT(B906,1)="H",LEFT(B906,1)="S")),3,"")) | Y906: =IF(U906=1,1,IF(AND(E906="LD1",U905=1),1,IF(AND(E906="FD1",U904=1),1,0))) -> 0 | AA906: =IF(X906<>"",1,"")
A907: NS | B907: ECSER932n | C907: 24GE04S0B | D907: 10M | E907: RFS | F907: ECSER932nA24 | G907: ER2411 | K907: =IF(D907="INT",1,"") | L907: =IF(AND(LEFT(B907,1)="E",A907<>"E",RIGHT(B907,1)="M"),IF(AND(A907="w",D907="MID",E907="RFS"),1,IF(AND(A907="C",D907="5M",E907="RFS"),1,"")),IF(AND(RIGHT(B907,1)="M",D907="10M",E907="RFS"),1,"")) | M907: =IF(L907=1,1,"") | N907: =IF(M907=1,1,"") | O907: =IF(N907=1,1,"") | P907: =IF(O907=1,1,"") | Q907: =IF(AND(OR(D907="INT",D907="DCL"),OR(LEFT(B907,2)="SU",LEFT(B907,2)="HU",LEFT(B907,2)="MI",LEFT(B907,2)="CS",LEFT(B907,2)="ON")),2,IF(AND(OR(D907="INT",D907="DCL"),LEFT(B907,2)="ER"),1,"")) | R907: =IF(D907="benthos",1,"") | S907: =IF(D907="mysis",1,"") | T907: =IF(AND(OR(D907="d20",D907="d100"),LEFT(B907,2)="SU"),2,IF(OR(D907="D20",D907="d100"),1,"")) | U907: =IF(VLOOKUP(C907,'QA Table'!$Y$5:$Y$20,1,TRUE)=C907,1,0) -> 0 | V907: =IF(AND(D907="Sediment",RIGHT(C907,1)="8"),1,"") | W907: =IF(AND(D907="Sediment",RIGHT(C907,1)="9"),1,"") | X907: =IF(AND(H907=1,OR(LEFT(B907,1)="M",LEFT(B907,1)="E",LEFT(B907,1)="O",LEFT(B907,1)="C")),4,IF(AND(H907=1,OR(LEFT(B907,1)="H",LEFT(B907,1)="S")),3,"")) | Y907: =IF(U907=1,1,IF(AND(E907="LD1",U906=1),1,IF(AND(E907="FD1",U905=1),1,0))) -> 0 | AA907: =IF(X907<>"",1,"")
A908: NS | B908: ECSER932n | C908: 24GE04S0C | D908: 20M | E908: RFS | F908: ECSER932nA24 | G908: ER2411 | K908: =IF(D908="INT",1,"") | L908: =IF(AND(LEFT(B908,1)="E",A908<>"E",RIGHT(B908,1)="M"),IF(AND(A908="w",D908="MID",E908="RFS"),1,IF(AND(A908="C",D908="5M",E908="RFS"),1,"")),IF(AND(RIGHT(B908,1)="M",D908="10M",E908="RFS"),1,"")) | M908: =IF(L908=1,1,"") | N908: =IF(M908=1,1,"") | O908: =IF(N908=1,1,"") | P908: =IF(O908=1,1,"") | Q908: =IF(AND(OR(D908="INT",D908="DCL"),OR(LEFT(B908,2)="SU",LEFT(B908,2)="HU",LEFT(B908,2)="MI",LEFT(B908,2)="CS",LEFT(B908,2)="ON")),2,IF(AND(OR(D908="INT",D908="DCL"),LEFT(B908,2)="ER"),1,"")) | R908: =IF(D908="benthos",1,"") | S908: =IF(D908="mysis",1,"") | T908: =IF(AND(OR(D908="d20",D908="d100"),LEFT(B908,2)="SU"),2,IF(OR(D908="D20",D908="d100"),1,"")) | U908: =IF(VLOOKUP(C908,'QA Table'!$Y$5:$Y$20,1,TRUE)=C908,1,0) -> 0 | V908: =IF(AND(D908="Sediment",RIGHT(C908,1)="8"),1,"") | W908: =IF(AND(D908="Sediment",RIGHT(C908,1)="9"),1,"") | X908: =IF(AND(H908=1,OR(LEFT(B908,1)="M",LEFT(B908,1)="E",LEFT(B908,1)="O",LEFT(B908,1)="C")),4,IF(AND(H908=1,OR(LEFT(B908,1)="H",LEFT(B908,1)="S")),3,"")) | Y908: =IF(U908=1,1,IF(AND(E908="LD1",U907=1),1,IF(AND(E908="FD1",U906=1),1,0))) -> 0 | AA908: =IF(X908<>"",1,"")
A909: NS | B909: ECSER932n | C909: 24GE04I12 | D909: INT | E909: RFS | F909: ECSER932nA24 | G909: ER2411 | H909: 1 | K909: =IF(D909="INT",1,"") -> 1 | L909: =IF(AND(LEFT(B909,1)="E",A909<>"E",RIGHT(B909,1)="M"),IF(AND(A909="w",D909="MID",E909="RFS"),1,IF(AND(A909="C",D909="5M",E909="RFS"),1,"")),IF(AND(RIGHT(B909,1)="M",D909="10M",E909="RFS"),1,"")) | M909: =IF(L909=1,1,"") | N909: =IF(M909=1,1,"") | O909: =IF(N909=1,1,"") | P909: =IF(O909=1,1,"") | Q909: 1 | R909: =IF(D909="benthos",1,"") | S909: =IF(D909="mysis",1,"") | T909: =IF(AND(OR(D909="d20",D909="d100"),LEFT(B909,2)="SU"),2,IF(OR(D909="D20",D909="d100"),1,"")) | U909: =IF(VLOOKUP(C909,'QA Table'!$Y$5:$Y$20,1,TRUE)=C909,1,0) -> 0 | V909: =IF(AND(D909="Sediment",RIGHT(C909,1)="8"),1,"") | W909: =IF(AND(D909="Sediment",RIGHT(C909,1)="9"),1,"") | X909: =IF(AND(H909=1,OR(LEFT(B909,1)="M",LEFT(B909,1)="E",LEFT(B909,1)="O",LEFT(B909,1)="C")),4,IF(AND(H909=1,OR(LEFT(B909,1)="H",LEFT(B909,1)="S")),3,"")) -> 4 | Y909: =IF(U909=1,1,IF(AND(E909="LD1",U908=1),1,IF(AND(E909="FD1",U907=1),1,0))) -> 0 | AA909: =IF(X909<>"",1,"") -> 1
A910: NS | B910: ECSER932n | C910: 24GE04I14 | D910: D20 | E910: RFS | F910: ECSER932nA24 | G910: ER2411 | K910: =IF(D910="INT",1,"") | L910: =IF(AND(LEFT(B910,1)="E",A910<>"E",RIGHT(B910,1)="M"),IF(AND(A910="w",D910="MID",E910="RFS"),1,IF(AND(A910="C",D910="5M",E910="RFS"),1,"")),IF(AND(RIGHT(B910,1)="M",D910="10M",E910="RFS"),1,"")) | M910: =IF(L910=1,1,"") | N910: =IF(M910=1,1,"") | O910: =IF(N910=1,1,"") | P910: =IF(O910=1,1,"") | R910: =IF(D910="benthos",1,"") | S910: =IF(D910="mysis",1,"") | T910: =IF(AND(OR(D910="d20",D910="d100"),LEFT(B910,2)="SU"),2,IF(OR(D910="D20",D910="d100"),1,"")) -> 1 | U910: =IF(VLOOKUP(C910,'QA Table'!$Y$5:$Y$20,1,TRUE)=C910,1,0) -> 0 | V910: =IF(AND(D910="Sediment",RIGHT(C910,1)="8"),1,"") | W910: =IF(AND(D910="Sediment",RIGHT(C910,1)="9"),1,"") | X910: =IF(AND(H910=1,OR(LEFT(B910,1)="M",LEFT(B910,1)="E",LEFT(B910,1)="O",LEFT(B910,1)="C")),4,IF(AND(H910=1,OR(LEFT(B910,1)="H",LEFT(B910,1)="S")),3,"")) | Y910: =IF(U910=1,1,IF(AND(E910="LD1",U909=1),1,IF(AND(E910="FD1",U908=1),1,0))) -> 0 | AA910: =IF(X910<>"",1,"")
A911: NS | B911: ECSER936n | C911: 24GE04S21 | D911: SRF | E911: RFS | F911: ECSER936nA24 | G911: ER2411 | J911: 1 | K911: =IF(D911="INT",1,"") | L911: =IF(AND(LEFT(B911,1)="E",A911<>"E",RIGHT(B911,1)="M"),IF(AND(A911="w",D911="MID",E911="RFS"),1,IF(AND(A911="C",D911="5M",E911="RFS"),1,"")),IF(AND(RIGHT(B911,1)="M",D911="10M",E911="RFS"),1,"")) | M911: =IF(L911=1,1,"") | N911: =IF(M911=1,1,"") | O911: =IF(N911=1,1,"") | P911: =IF(O911=1,1,"") | Q911: =IF(AND(OR(D911="INT",D911="DCL"),OR(LEFT(B911,2)="SU",LEFT(B911,2)="HU",LEFT(B911,2)="MI",LEFT(B911,2)="CS",LEFT(B911,2)="ON")),2,IF(AND(OR(D911="INT",D911="DCL"),LEFT(B911,2)="ER"),1,"")) | R911: =IF(D911="benthos",1,"") | S911: =IF(D911="mysis",1,"") | T911: =IF(AND(OR(D911="d20",D911="d100"),LEFT(B911,2)="SU"),2,IF(OR(D911="D20",D911="d100"),1,"")) | U911: =IF(VLOOKUP(C911,'QA Table'!$Y$5:$Y$20,1,TRUE)=C911,1,0) -> 0 | V911: =IF(AND(D911="Sediment",RIGHT(C911,1)="8"),1,"") | W911: =IF(AND(D911="Sediment",RIGHT(C911,1)="9"),1,"") | X911: =IF(AND(H911=1,OR(LEFT(B911,1)="M",LEFT(B911,1)="E",LEFT(B911,1)="O",LEFT(B911,1)="C")),4,IF(AND(H911=1,OR(LEFT(B911,1)="H",LEFT(B911,1)="S")),3,"")) | Y911: =IF(U911=1,1,IF(AND(E911="LD1",U910=1),1,IF(AND(E911="FD1",U909=1),1,0))) -> 0 | AA911: =IF(X911<>"",1,"")
A912: NS | B912: ECSER936n | C912: 24GE04S2A | D912: 5M | E912: RFS | F912: ECSER936nA24 | G912: ER2411 | K912: =IF(D912="INT",1,"") | L912: =IF(AND(LEFT(B912,1)="E",A912<>"E",RIGHT(B912,1)="M"),IF(AND(A912="w",D912="MID",E912="RFS"),1,IF(AND(A912="C",D912="5M",E912="RFS"),1,"")),IF(AND(RIGHT(B912,1)="M",D912="10M",E912="RFS"),1,"")) | M912: =IF(L912=1,1,"") | N912: =IF(M912=1,1,"") | O912: =IF(N912=1,1,"") | P912: =IF(O912=1,1,"") | Q912: =IF(AND(OR(D912="INT",D912="DCL"),OR(LEFT(B912,2)="SU",LEFT(B912,2)="HU",LEFT(B912,2)="MI",LEFT(B912,2)="CS",LEFT(B912,2)="ON")),2,IF(AND(OR(D912="INT",D912="DCL"),LEFT(B912,2)="ER"),1,"")) | R912: =IF(D912="benthos",1,"") | S912: =IF(D912="mysis",1,"") | T912: =IF(AND(OR(D912="d20",D912="d100"),LEFT(B912,2)="SU"),2,IF(OR(D912="D20",D912="d100"),1,"")) | U912: =IF(VLOOKUP(C912,'QA Table'!$Y$5:$Y$20,1,TRUE)=C912,1,0) -> 0 | V912: =IF(AND(D912="Sediment",RIGHT(C912,1)="8"),1,"") | W912: =IF(AND(D912="Sediment",RIGHT(C912,1)="9"),1,"") | X912: =IF(AND(H912=1,OR(LEFT(B912,1)="M",LEFT(B912,1)="E",LEFT(B912,1)="O",LEFT(B912,1)="C")),4,IF(AND(H912=1,OR(LEFT(B912,1)="H",LEFT(B912,1)="S")),3,"")) | Y912: =IF(U912=1,1,IF(AND(E912="LD1",U911=1),1,IF(AND(E912="FD1",U910=1),1,0))) -> 0 | AA912: =IF(X912<>"",1,"")
A913: NS | B913: ECSER936n | C913: 24GE04S2B | D913: 10M | E913: RFS | F913: ECSER936nA24 | G913: ER2411 | K913: =IF(D913="INT",1,"") | L913: =IF(AND(LEFT(B913,1)="E",A913<>"E",RIGHT(B913,1)="M"),IF(AND(A913="w",D913="MID",E913="RFS"),1,IF(AND(A913="C",D913="5M",E913="RFS"),1,"")),IF(AND(RIGHT(B913,1)="M",D913="10M",E913="RFS"),1,"")) | M913: =IF(L913=1,1,"") | N913: =IF(M913=1,1,"") | O913: =IF(N913=1,1,"") | P913: =IF(O913=1,1,"") | Q913: =IF(AND(OR(D913="INT",D913="DCL"),OR(LEFT(B913,2)="SU",LEFT(B913,2)="HU",LEFT(B913,2)="MI",LEFT(B913,2)="CS",LEFT(B913,2)="ON")),2,IF(AND(OR(D913="INT",D913="DCL"),LEFT(B913,2)="ER"),1,"")) | R913: =IF(D913="benthos",1,"") | S913: =IF(D913="mysis",1,"") | T913: =IF(AND(OR(D913="d20",D913="d100"),LEFT(B913,2)="SU"),2,IF(OR(D913="D20",D913="d100"),1,"")) | U913: =IF(VLOOKUP(C913,'QA Table'!$Y$5:$Y$20,1,TRUE)=C913,1,0) -> 0 | V913: =IF(AND(D913="Sediment",RIGHT(C913,1)="8"),1,"") | W913: =IF(AND(D913="Sediment",RIGHT(C913,1)="9"),1,"") | X913: =IF(AND(H913=1,OR(LEFT(B913,1)="M",LEFT(B913,1)="E",LEFT(B913,1)="O",LEFT(B913,1)="C")),4,IF(AND(H913=1,OR(LEFT(B913,1)="H",LEFT(B913,1)="S")),3,"")) | Y913: =IF(U913=1,1,IF(AND(E913="LD1",U912=1),1,IF(AND(E913="FD1",U911=1),1,0))) -> 0 | AA913: =IF(X913<>"",1,"")
A914: NS | B914: ECSER936n | C914: 24GE04S2C | D914: 20M | E914: RFS | F914: ECSER936nA24 | G914: ER2411 | K914: =IF(D914="INT",1,"") | L914: =IF(AND(LEFT(B914,1)="E",A914<>"E",RIGHT(B914,1)="M"),IF(AND(A914="w",D914="MID",E914="RFS"),1,IF(AND(A914="C",D914="5M",E914="RFS"),1,"")),IF(AND(RIGHT(B914,1)="M",D914="10M",E914="RFS"),1,"")) | M914: =IF(L914=1,1,"") | N914: =IF(M914=1,1,"") | O914: =IF(N914=1,1,"") | P914: =IF(O914=1,1,"") | Q914: =IF(AND(OR(D914="INT",D914="DCL"),OR(LEFT(B914,2)="SU",LEFT(B914,2)="HU",LEFT(B914,2)="MI",LEFT(B914,2)="CS",LEFT(B914,2)="ON")),2,IF(AND(OR(D914="INT",D914="DCL"),LEFT(B914,2)="ER"),1,"")) | R914: =IF(D914="benthos",1,"") | S914: =IF(D914="mysis",1,"") | T914: =IF(AND(OR(D914="d20",D914="d100"),LEFT(B914,2)="SU"),2,IF(OR(D914="D20",D914="d100"),1,"")) | U914: =IF(VLOOKUP(C914,'QA Table'!$Y$5:$Y$20,1,TRUE)=C914,1,0) -> 0 | V914: =IF(AND(D914="Sediment",RIGHT(C914,1)="8"),1,"") | W914: =IF(AND(D914="Sediment",RIGHT(C914,1)="9"),1,"") | X914: =IF(AND(H914=1,OR(LEFT(B914,1)="M",LEFT(B914,1)="E",LEFT(B914,1)="O",LEFT(B914,1)="C")),4,IF(AND(H914=1,OR(LEFT(B914,1)="H",LEFT(B914,1)="S")),3,"")) | Y914: =IF(U914=1,1,IF(AND(E914="LD1",U913=1),1,IF(AND(E914="FD1",U912=1),1,0))) -> 0 | AA914: =IF(X914<>"",1,"")
A915: NS | B915: ECSER936n | C915: 24GE04I32 | D915: INT | E915: RFS | F915: ECSER936nA24 | G915: ER2411 | H915: 1 | K915: =IF(D915="INT",1,"") -> 1 | L915: =IF(AND(LEFT(B915,1)="E",A915<>"E",RIGHT(B915,1)="M"),IF(AND(A915="w",D915="MID",E915="RFS"),1,IF(AND(A915="C",D915="5M",E915="RFS"),1,"")),IF(AND(RIGHT(B915,1)="M",D915="10M",E915="RFS"),1,"")) | M915: =IF(L915=1,1,"") | N915: =IF(M915=1,1,"") | O915: =IF(N915=1,1,"") | P915: =IF(O915=1,1,"") | Q915: 1 | R915: =IF(D915="benthos",1,"") | S915: =IF(D915="mysis",1,"") | T915: =IF(AND(OR(D915="d20",D915="d100"),LEFT(B915,2)="SU"),2,IF(OR(D915="D20",D915="d100"),1,"")) | U915: =IF(VLOOKUP(C915,'QA Table'!$Y$5:$Y$20,1,TRUE)=C915,1,0) -> 0 | V915: =IF(AND(D915="Sediment",RIGHT(C915,1)="8"),1,"") | W915: =IF(AND(D915="Sediment",RIGHT(C915,1)="9"),1,"") | X915: =IF(AND(H915=1,OR(LEFT(B915,1)="M",LEFT(B915,1)="E",LEFT(B915,1)="O",LEFT(B915,1)="C")),4,IF(AND(H915=1,OR(LEFT(B915,1)="H",LEFT(B915,1)="S")),3,"")) -> 4 | Y915: =IF(U915=1,1,IF(AND(E915="LD1",U914=1),1,IF(AND(E915="FD1",U913=1),1,0))) -> 0 | AA915: =IF(X915<>"",1,"") -> 1
A916: NS | B916: ECSER936n | C916: 24GE04I34 | D916: D20 | E916: RFS | F916: ECSER936nA24 | G916: ER2411 | K916: =IF(D916="INT",1,"") | L916: =IF(AND(LEFT(B916,1)="E",A916<>"E",RIGHT(B916,1)="M"),IF(AND(A916="w",D916="MID",E916="RFS"),1,IF(AND(A916="C",D916="5M",E916="RFS"),1,"")),IF(AND(RIGHT(B916,1)="M",D916="10M",E916="RFS"),1,"")) | M916: =IF(L916=1,1,"") | N916: =IF(M916=1,1,"") | O916: =IF(N916=1,1,"") | P916: =IF(O916=1,1,"") | R916: =IF(D916="benthos",1,"") | S916: =IF(D916="mysis",1,"") | T916: =IF(AND(OR(D916="d20",D916="d100"),LEFT(B916,2)="SU"),2,IF(OR(D916="D20",D916="d100"),1,"")) -> 1 | U916: =IF(VLOOKUP(C916,'QA Table'!$Y$5:$Y$20,1,TRUE)=C916,1,0) -> 0 | V916: =IF(AND(D916="Sediment",RIGHT(C916,1)="8"),1,"") | W916: =IF(AND(D916="Sediment",RIGHT(C916,1)="9"),1,"") | X916: =IF(AND(H916=1,OR(LEFT(B916,1)="M",LEFT(B916,1)="E",LEFT(B916,1)="O",LEFT(B916,1)="C")),4,IF(AND(H916=1,OR(LEFT(B916,1)="H",LEFT(B916,1)="S")),3,"")) | Y916: =IF(U916=1,1,IF(AND(E916="LD1",U915=1),1,IF(AND(E916="FD1",U914=1),1,0))) -> 0 | AA916: =IF(X916<>"",1,"")
A917: NS | B917: ECSER937n | C917: 24GE04S41 | D917: SRF | E917: RFS | F917: ECSER937nA24 | G917: ER2411 | J917: 1 | K917: =IF(D917="INT",1,"") | L917: =IF(AND(LEFT(B917,1)="E",A917<>"E",RIGHT(B917,1)="M"),IF(AND(A917="w",D917="MID",E917="RFS"),1,IF(AND(A917="C",D917="5M",E917="RFS"),1,"")),IF(AND(RIGHT(B917,1)="M",D917="10M",E917="RFS"),1,"")) | M917: =IF(L917=1,1,"") | N917: =IF(M917=1,1,"") | O917: =IF(N917=1,1,"") | P917: =IF(O917=1,1,"") | Q917: =IF(AND(OR(D917="INT",D917="DCL"),OR(LEFT(B917,2)="SU",LEFT(B917,2)="HU",LEFT(B917,2)="MI",LEFT(B917,2)="CS",LEFT(B917,2)="ON")),2,IF(AND(OR(D917="INT",D917="DCL"),LEFT(B917,2)="ER"),1,"")) | R917: =IF(D917="benthos",1,"") | S917: =IF(D917="mysis",1,"") | T917: =IF(AND(OR(D917="d20",D917="d100"),LEFT(B917,2)="SU"),2,IF(OR(D917="D20",D917="d100"),1,"")) | U917: =IF(VLOOKUP(C917,'QA Table'!$Y$5:$Y$20,1,TRUE)=C917,1,0) -> 0 | V917: =IF(AND(D917="Sediment",RIGHT(C917,1)="8"),1,"") | W917: =IF(AND(D917="Sediment",RIGHT(C917,1)="9"),1,"") | X917: =IF(AND(H917=1,OR(LEFT(B917,1)="M",LEFT(B917,1)="E",LEFT(B917,1)="O",LEFT(B917,1)="C")),4,IF(AND(H917=1,OR(LEFT(B917,1)="H",LEFT(B917,1)="S")),3,"")) | Y917: =IF(U917=1,1,IF(AND(E917="LD1",U916=1),1,IF(AND(E917="FD1",U915=1),1,0))) -> 0 | AA917: =IF(X917<>"",1,"")
